Workbook

Sheet Sheet1
S1: 1 | T1: 2 | U1: 3 | V1: 4 | W1: 5 | X1: 6 | Y1: 7 | Z1: 8 | AA1: 9 | AB1: 10 | AC1: 11 | AD1: 12 | AE1: 13 | AF1: 14 | AG1: 15 | AH1: 16 | AI1: 17 | AJ1: 24
A2: Kode Deskel | B2: Nama Deskel | C2: pemilih_dpt_l | D2: pemilih_dpt_p | E2: pemilih_dpt_j | F2: pengguna_dpt_l | G2: pengguna_dpt_p | H2: pengguna_dpt_j | I2: pengguna_dptb_l | J2: pengguna_dptb_p | K2: pengguna_dptb_j | L2: pengguna_dpk_l | M2: pengguna_dpk_p | N2: pengguna_dpk_j | O2: PPWP 01 | P2: PPWP 02 | Q2: PPWP 03 | R2: Total PPWP | S2: Partai Kebangkitan Bangsa | T2: Partai Gerakan Indonesia Raya | U2: Partai Demokrasi Indonesia Perjuangan | V2: Partai Golongan Karya | W2: Partai NasDem | X2: Partai Buruh | Y2: Partai Gelombang Rakyat Indonesia | Z2: Partai Keadilan Sejahtera | AA2: Partai Kebangkitan Nusantara | AB2: Partai Hati Nurani Rakyat | AC2: Partai Garda Republik Indonesia | AD2: Partai Amanat Nasional | AE2: Partai Bulan Bintang | AF2: Partai Demokrat | AG2: Partai Solidaritas Indonesia | AH2: PARTAI PERINDO | AI2: Partai Persatuan Pembangunan | AJ2: Partai Ummat | AK2: Total DPR
A3: 74.08.03.1001 | B3: BATU PUTIH | C3: 548 | D3: 569 | E3: 1117 | F3: 458 | G3: 513 | H3: 971 | I3: 7 | J3: 3 | K3: 10 | L3: 11 | M3: 7 | N3: 18 | O3: 371 | P3: 593 | Q3: 19 | R3: 983 | S3: 76 | T3: 264 | U3: 41 | V3: 24 | W3: 39 | X3: 2 | Y3: 2 | Z3: 50 | AA3: 0 | AB3: 6 | AC3: 2 | AD3: 13 | AE3: 7 | AF3: 371 | AG3: 3 | AH3: 0 | AI3: 40 | AJ3: 0 | AK3: 940
A4: 74.08.03.2002 | B4: LATOWU | C4: 446 | D4: 460 | E4: 906 | F4: 386 | G4: 409 | H4: 795 | I4: 6 | J4: 7 | K4: 13 | L4: 5 | M4: 1 | N4: 6 | O4: 332 | P4: 460 | Q4: 15 | R4: 807 | S4: 76 | T4: 193 | U4: 66 | V4: 30 | W4: 49 | X4: 2 | Y4: 4 | Z4: 33 | AA4: 1 | AB4: 0 | AC4: 0 | AD4: 11 | AE4: 12 | AF4: 278 | AG4: 0 | AH4: 0 | AI4: 30 | AJ4: 1 | AK4: 786
A5: 74.08.03.2003 | B5: MOSIKU | C5: 415 | D5: 398 | E5: 813 | F5: 330 | G5: 349 | H5: 679 | I5: 3 | J5: 4 | K5: 7 | L5: 4 | M5: 5 | N5: 9 | O5: 123 | P5: 554 | Q5: 13 | R5: 690 | S5: 38 | T5: 315 | U5: 53 | V5: 13 | W5: 25 | X5: 3 | Y5: 1 | Z5: 61 | AA5: 0 | AB5: 3 | AC5: 0 | AD5: 2 | AE5: 2 | AF5: 128 | AG5: 4 | AH5: 1 | AI5: 18 | AJ5: 0 | AK5: 667
A6: 74.08.03.2004 | B6: LELEWAWO | C6: 453 | D6: 442 | E6: 895 | F6: 398 | G6: 408 | H6: 806 | I6: 12 | J6: 7 | K6: 19 | L6: 14 | M6: 10 | N6: 24 | O6: 301 | P6: 525 | Q6: 9 | R6: 835 | S6: 50 | T6: 211 | U6: 41 | V6: 33 | W6: 73 | X6: 8 | Y6: 5 | Z6: 26 | AA6: 2 | AB6: 4 | AC6: 1 | AD6: 2 | AE6: 8 | AF6: 196 | AG6: 0 | AH6: 1 | AI6: 126 | AJ6: 0 | AK6: 787
A7: 74.08.03.2011 | B7: BATU API | C7: 78 | D7: 71 | E7: 149 | F7: 55 | G7: 60 | H7: 115 | I7: 1 | J7: 0 | K7: 1 | L7: 0 | M7: 0 | N7: 0 | O7: 59 | P7: 55 | Q7: 2 | R7: 116 | S7: 6 | T7: 15 | U7: 0 | V7: 8 | W7: 3 | X7: 1 | Y7: 0 | Z7: 1 | AA7: 0 | AB7: 0 | AC7: 0 | AD7: 0 | AE7: 0 | AF7: 78 | AG7: 0 | AH7: 0 | AI7: 2 | AJ7: 0 | AK7: 114
A8: 74.08.03.2012 | B8: BUKIT TINGGI | C8: 248 | D8: 250 | E8: 498 | F8: 219 | G8: 222 | H8: 441 | I8: 3 | J8: 4 | K8: 7 | L8: 4 | M8: 4 | N8: 8 | O8: 147 | P8: 278 | Q8: 26 | R8: 451 | S8: 85 | T8: 205 | U8: 46 | V8: 8 | W8: 19 | X8: 5 | Y8: 2 | Z8: 4 | AA8: 2 | AB8: 1 | AC8: 2 | AD8: 1 | AE8: 1 | AF8: 39 | AG8: 1 | AH8: 1 | AI8: 1 | AJ8: 1 | AK8: 424
A9: 74.08.03.2015 | B9: BUKIT BARU | C9: 220 | D9: 173 | E9: 393 | F9: 181 | G9: 150 | H9: 331 | I9: 4 | J9: 5 | K9: 9 | L9: 1 | M9: 5 | N9: 6 | O9: 108 | P9: 220 | Q9: 14 | R9: 342 | S9: 48 | T9: 94 | U9: 104 | V9: 6 | W9: 4 | X9: 2 | Y9: 2 | Z9: 1 | AA9: 2 | AB9: 1 | AC9: 1 | AD9: 1 | AE9: 7 | AF9: 49 | AG9: 0 | AH9: 0 | AI9: 3 | AJ9: 2 | AK9: 327
A10: 74.08.03.2016 | B10: PARUNG LAMPE | C10: 104 | D10: 100 | E10: 204 | F10: 89 | G10: 84 | H10: 173 | I10: 0 | J10: 1 | K10: 1 | L10: 1 | M10: 1 | N10: 2 | O10: 82 | P10: 92 | Q10: 2 | R10: 176 | S10: 37 | T10: 46 | U10: 6 | V10: 2 | W10: 4 | X10: 2 | Y10: 0 | Z10: 1 | AA10: 0 | AB10: 0 | AC10: 0 | AD10: 0 | AE10: 1 | AF10: 71 | AG10: 1 | AH10: 0 | AI10: 2 | AJ10: 0 | AK10: 173
A11: 74.08.03.2017 | B11: PUNCAK HARAPAN | C11: 133 | D11: 131 | E11: 264 | F11: 104 | G11: 119 | H11: 223 | I11: 3 | J11: 4 | K11: 7 | L11: 1 | M11: 1 | N11: 2 | O11: 98 | P11: 127 | Q11: 5 | R11: 230 | S11: 16 | T11: 110 | U11: 6 | V11: 1 | W11: 2 | X11: 2 | Y11: 0 | Z11: 1 | AA11: 0 | AB11: 1 | AC11: 0 | AD11: 0 | AE11: 0 | AF11: 79 | AG11: 0 | AH11: 1 | AI11: 10 | AJ11: 0 | AK11: 229
A12: 74.08.03.2020 | B12: TETEBAWO | C12: 151 | D12: 137 | E12: 288 | F12: 120 | G12: 118 | H12: 238 | I12: 3 | J12: 3 | K12: 6 | L12: 1 | M12: 0 | N12: 1 | O12: 48 | P12: 194 | Q12: 2 | R12: 244 | S12: 10 | T12: 29 | U12: 14 | V12: 26 | W12: 3 | X12: 1 | Y12: 0 | Z12: 21 | AA12: 0 | AB12: 0 | AC12: 1 | AD12: 1 | AE12: 5 | AF12: 114 | AG12: 1 | AH12: 3 | AI12: 7 | AJ12: 1 | AK12: 237
A13: 74.08.03.2021 | B13: MAKKUASENG | C13: 207 | D13: 229 | E13: 436 | F13: 168 | G13: 193 | H13: 361 | I13: 2 | J13: 2 | K13: 4 | L13: 3 | M13: 0 | N13: 3 | O13: 102 | P13: 259 | Q13: 3 | R13: 364 | S13: 50 | T13: 66 | U13: 23 | V13: 19 | W13: 34 | X13: 0 | Y13: 1 | Z13: 9 | AA13: 0 | AB13: 1 | AC13: 0 | AD13: 1 | AE13: 71 | AF13: 73 | AG13: 0 | AH13: 1 | AI13: 8 | AJ13: 0 | AK13: 357
A14: Total | C14: 3003 | D14: 2960 | E14: 5963 | F14: 2508 | G14: 2625 | H14: 5133 | I14: 44 | J14: 40 | K14: 84 | L14: 45 | M14: 34 | N14: 79 | O14: 1771 | P14: 3357 | Q14: 110 | R14: 5238 | S14: 492 | T14: 1548 | U14: 400 | V14: 170 | W14: 255 | X14: 28 | Y14: 17 | Z14: 208 | AA14: 7 | AB14: 17 | AC14: 7 | AD14: 32 | AE14: 114 | AF14: 1476 | AG14: 10 | AH14: 8 | AI14: 247 | AJ14: 5 | AK14: 5041
B21: laki-laki | C21: perempuan | D21: total | E21: tidak punya ijazah | F21: tk/paud | G21: sd/sederajat | H21: smp/sederajat | I21: sma/sederajat | J21: smk/sederajat | K21: d1/d2/d3 | L21: d4/s1 | M21: s2 | N21: s3 | O21: belum/tidak bekerja | P21: koki/barista/bartender | Q21: pekerja serabutan | R21: petani/pekebun | S21: wirausaha | T21: ustadz/mubaligh | U21: guru/pendidik | V21: polisi | W21: buruh industri | X21: pekerja/karyawan swasta | Y21: tenaga administrasi (tata usaha) | Z21: montir/mekanik/teknisi | AA21: peternak | AB21: driver/pengemudi | AC21: pembantu/asisten rumah tangga | AD21: bidan | AE21: pejabat lembaga negara | AF21: penjahit/tukang sol | AG21: seniman | AH21: pelatih/instruktur/pawang | AI21: perawat | AJ21: pelaut | AK21: pemuka agama/adat | AL21: kontraktor (pemborong) | AM21: operator alat berat | AN21: security/satpam/penjaga keamanan | AO21: arsitek | AP21: sekretaris | AQ21: buruh bangunan | AR21: tni | AS21: buruh tani | AT21: debt collector/penagih hutang | AU21: pelayan/penjaga toko | AV21: customer service/resepsionis/teller | AW21: dosen | AX21: pegawai lembaga negara | AY21: perangkat desa | AZ21: penata rias | BA21: nelayan | BB21: mandor/pengawas/supervisor | BC21: public relation/marketing | BD21: kasir | BE21: peneliti | BF21: pengrajin | BG21: petambak | BH21: pramugara/pramugari | BI21: kurir | BJ21: dokter | BK21: ya | BL21: tidak | BO21: Ya | BP21: Tidak
A22: 74.08.03.1001 | B22: 534 | C22: 546 | D22: 1080 | E22: 128 | F22: 4 | G22: 254 | H22: 162 | I22: 333 | J22: 23 | K22: 33 | L22: 138 | M22: 4 | N22: 1 | O22: 562 | P22: 2 | Q22: 18 | R22: 266 | S22: 43 | T22: 2 | U22: 49 | V22: 0 | W22: 24 | X22: 20 | Y22: 14 | Z22: 6 | AA22: 2 | AB22: 10 | AC22: 6 | AD22: 15 | AE22: 1 | AF22: 2 | AG22: 1 | AH22: 1 | AI22: 6 | AJ22: 4 | AK22: 1 | AL22: 1 | AM22: 2 | AN22: 2 | AO22: 2 | AP22: 2 | AQ22: 5 | AR22: 0 | AS22: 4 | AT22: 1 | AU22: 2 | AV22: 1 | AW22: 1 | AX22: 2 | AY22: 0 | AZ22: 0 | BA22: 0 | BB22: 0 | BC22: 0 | BD22: 0 | BE22: 0 | BF22: 0 | BG22: 0 | BH22: 0 | BI22: 0 | BJ22: 0 | BK22: 252 | BL22: 828 | BM22: =SUM(BK22:BL22) -> 1080 | BN22: {=B3:B13} -> BATU PUTIH | BO22: =BK22/$BM22 -> 0.23333333 | BP22: =BL22/$BM22 -> 0.76666667
A23: 74.08.03.2002 | B23: 389 | C23: 406 | D23: 795 | E23: 58 | F23: 2 | G23: 225 | H23: 132 | I23: 283 | J23: 7 | K23: 19 | L23: 69 | M23: 0 | N23: 0 | O23: 483 | P23: 0 | Q23: 34 | R23: 152 | S23: 16 | T23: 0 | U23: 28 | V23: 0 | W23: 14 | X23: 9 | Y23: 5 | Z23: 3 | AA23: 2 | AB23: 12 | AC23: 0 | AD23: 10 | AE23: 0 | AF23: 2 | AG23: 0 | AH23: 0 | AI23: 3 | AJ23: 4 | AK23: 0 | AL23: 2 | AM23: 1 | AN23: 3 | AO23: 0 | AP23: 0 | AQ23: 6 | AR23: 0 | AS23: 0 | AT23: 0 | AU23: 0 | AV23: 0 | AW23: 1 | AX23: 0 | AY23: 3 | AZ23: 1 | BA23: 1 | BB23: 0 | BC23: 0 | BD23: 0 | BE23: 0 | BF23: 0 | BG23: 0 | BH23: 0 | BI23: 0 | BJ23: 0 | BK23: 363 | BL23: 432 | BM23: =SUM(BK23:BL23) -> 795 | BN23: LATOWU | BO23: =BK23/$BM23 -> 0.45660377 | BP23: =BL23/$BM23 -> 0.54339623
A24: 74.08.03.2003 | B24: 373 | C24: 359 | D24: 732 | E24: 27 | F24: 7 | G24: 209 | H24: 173 | I24: 257 | J24: 11 | K24: 7 | L24: 40 | M24: 1 | N24: 0 | O24: 332 | P24: 1 | Q24: 7 | R24: 287 | S24: 4 | T24: 0 | U24: 20 | V24: 0 | W24: 10 | X24: 14 | Y24: 5 | Z24: 3 | AA24: 1 | AB24: 11 | AC24: 0 | AD24: 1 | AE24: 1 | AF24: 1 | AG24: 0 | AH24: 0 | AI24: 1 | AJ24: 2 | AK24: 0 | AL24: 14 | AM24: 1 | AN24: 2 | AO24: 0 | AP24: 0 | AQ24: 9 | AR24: 0 | AS24: 3 | AT24: 0 | AU24: 1 | AV24: 0 | AW24: 0 | AX24: 0 | AY24: 0 | AZ24: 0 | BA24: 1 | BB24: 0 | BC24: 0 | BD24: 0 | BE24: 0 | BF24: 0 | BG24: 0 | BH24: 0 | BI24: 0 | BJ24: 0 | BK24: 177 | BL24: 555 | BM24: =SUM(BK24:BL24) -> 732 | BN24: MOSIKU | BO24: =BK24/$BM24 -> 0.24180328 | BP24: =BL24/$BM24 -> 0.75819672
A25: 74.08.03.2004 | B25: 401 | C25: 435 | D25: 836 | E25: 65 | F25: 3 | G25: 269 | H25: 121 | I25: 271 | J25: 5 | K25: 16 | L25: 85 | M25: 1 | N25: 0 | O25: 409 | P25: 0 | Q25: 6 | R25: 273 | S25: 13 | T25: 0 | U25: 36 | V25: 0 | W25: 7 | X25: 12 | Y25: 7 | Z25: 2 | AA25: 0 | AB25: 4 | AC25: 0 | AD25: 4 | AE25: 2 | AF25: 0 | AG25: 0 | AH25: 0 | AI25: 2 | AJ25: 2 | AK25: 0 | AL25: 0 | AM25: 16 | AN25: 4 | AO25: 0 | AP25: 0 | AQ25: 4 | AR25: 0 | AS25: 0 | AT25: 0 | AU25: 2 | AV25: 0 | AW25: 0 | AX25: 0 | AY25: 6 | AZ25: 0 | BA25: 19 | BB25: 1 | BC25: 1 | BD25: 1 | BE25: 2 | BF25: 1 | BG25: 0 | BH25: 0 | BI25: 0 | BJ25: 0 | BK25: 26 | BL25: 810 | BM25: =SUM(BK25:BL25) -> 836 | BN25: LELEWAWO | BO25: =BK25/$BM25 -> 0.031100478 | BP25: =BL25/$BM25 -> 0.96889952
A26: 74.08.03.2011 | B26: 70 | C26: 74 | D26: 144 | E26: 30 | F26: 4 | G26: 32 | H26: 19 | I26: 44 | J26: 0 | K26: 2 | L26: 13 | M26: 0 | N26: 0 | O26: 68 | P26: 0 | Q26: 4 | R26: 39 | S26: 4 | T26: 0 | U26: 5 | V26: 0 | W26: 7 | X26: 0 | Y26: 1 | Z26: 2 | AA26: 0 | AB26: 1 | AC26: 0 | AD26: 1 | AE26: 1 | AF26: 0 | AG26: 0 | AH26: 0 | AI26: 2 | AJ26: 0 | AK26: 0 | AL26: 2 | AM26: 0 | AN26: 0 | AO26: 0 | AP26: 1 | AQ26: 1 | AR26: 0 | AS26: 0 | AT26: 0 | AU26: 0 | AV26: 0 | AW26: 0 | AX26: 0 | AY26: 5 | AZ26: 0 | BA26: 0 | BB26: 0 | BC26: 0 | BD26: 0 | BE26: 0 | BF26: 0 | BG26: 0 | BH26: 0 | BI26: 0 | BJ26: 0 | BK26: 58 | BL26: 86 | BM26: =SUM(BK26:BL26) -> 144 | BN26: BATU API | BO26: =BK26/$BM26 -> 0.40277778 | BP26: =BL26/$BM26 -> 0.59722222
A27: 74.08.03.2012 | B27: 201 | C27: 212 | D27: 413 | E27: 56 | F27: 8 | G27: 144 | H27: 68 | I27: 97 | J27: 15 | K27: 4 | L27: 21 | M27: 0 | N27: 0 | O27: 193 | P27: 0 | Q27: 5 | R27: 160 | S27: 9 | T27: 0 | U27: 6 | V27: 0 | W27: 5 | X27: 7 | Y27: 1 | Z27: 5 | AA27: 1 | AB27: 4 | AC27: 0 | AD27: 5 | AE27: 0 | AF27: 1 | AG27: 0 | AH27: 0 | AI27: 5 | AJ27: 0 | AK27: 1 | AL27: 0 | AM27: 1 | AN27: 0 | AO27: 0 | AP27: 1 | AQ27: 0 | AR27: 0 | AS27: 0 | AT27: 0 | AU27: 0 | AV27: 0 | AW27: 0 | AX27: 0 | AY27: 1 | AZ27: 0 | BA27: 1 | BB27: 0 | BC27: 0 | BD27: 0 | BE27: 0 | BF27: 0 | BG27: 1 | BH27: 0 | BI27: 0 | BJ27: 0 | BK27: 64 | BL27: 349 | BM27: =SUM(BK27:BL27) -> 413 | BN27: BUKIT TINGGI | BO27: =BK27/$BM27 -> 0.15496368 | BP27: =BL27/$BM27 -> 0.84503632
A28: 74.08.03.2015 | B28: 176 | C28: 161 | D28: 337 | E28: 51 | F28: 3 | G28: 171 | H28: 34 | I28: 63 | J28: 2 | K28: 4 | L28: 9 | M28: 0 | N28: 0 | O28: 182 | P28: 0 | Q28: 1 | R28: 144 | S28: 0 | T28: 0 | U28: 4 | V28: 0 | W28: 1 | X28: 2 | Y28: 1 | Z28: 0 | AA28: 0 | AB28: 0 | AC28: 0 | AD28: 0 | AE28: 1 | AF28: 0 | AG28: 0 | AH28: 0 | AI28: 0 | AJ28: 0 | AK28: 0 | AL28: 0 | AM28: 0 | AN28: 0 | AO28: 0 | AP28: 0 | AQ28: 0 | AR28: 0 | AS28: 0 | AT28: 0 | AU28: 0 | AV28: 0 | AW28: 0 | AX28: 0 | AY28: 0 | AZ28: 0 | BA28: 0 | BB28: 0 | BC28: 0 | BD28: 0 | BE28: 0 | BF28: 0 | BG28: 0 | BH28: 1 | BI28: 0 | BJ28: 0 | BK28: 15 | BL28: 322 | BM28: =SUM(BK28:BL28) -> 337 | BN28: BUKIT BARU | BO28: =BK28/$BM28 -> 0.044510386 | BP28: =BL28/$BM28 -> 0.95548961
A29: 74.08.03.2016 | B29: 85 | C29: 83 | D29: 168 | E29: 32 | F29: 1 | G29: 46 | H29: 29 | I29: 44 | J29: 3 | K29: 1 | L29: 12 | M29: 0 | N29: 0 | O29: 78 | P29: 0 | Q29: 1 | R29: 61 | S29: 2 | T29: 0 | U29: 4 | V29: 0 | W29: 1 | X29: 1 | Y29: 0 | Z29: 1 | AA29: 8 | AB29: 4 | AC29: 0 | AD29: 0 | AE29: 0 | AF29: 0 | AG29: 0 | AH29: 0 | AI29: 0 | AJ29: 0 | AK29: 0 | AL29: 0 | AM29: 1 | AN29: 0 | AO29: 0 | AP29: 0 | AQ29: 1 | AR29: 0 | AS29: 1 | AT29: 0 | AU29: 0 | AV29: 0 | AW29: 0 | AX29: 0 | AY29: 3 | AZ29: 0 | BA29: 0 | BB29: 0 | BC29: 0 | BD29: 1 | BE29: 0 | BF29: 0 | BG29: 0 | BH29: 0 | BI29: 0 | BJ29: 0 | BK29: 37 | BL29: 131 | BM29: =SUM(BK29:BL29) -> 168 | BN29: PARUNG LAMPE | BO29: =BK29/$BM29 -> 0.2202381 | BP29: =BL29/$BM29 -> 0.7797619
A30: 74.08.03.2017 | B30: 120 | C30: 125 | D30: 245 | E30: 64 | F30: 2 | G30: 83 | H30: 30 | I30: 42 | J30: 4 | K30: 0 | L30: 20 | M30: 0 | N30: 0 | O30: 86 | P30: 0 | Q30: 0 | R30: 123 | S30: 2 | T30: 0 | U30: 8 | V30: 0 | W30: 1 | X30: 0 | Y30: 1 | Z30: 1 | AA30: 1 | AB30: 0 | AC30: 18 | AD30: 0 | AE30: 1 | AF30: 1 | AG30: 0 | AH30: 0 | AI30: 0 | AJ30: 0 | AK30: 0 | AL30: 0 | AM30: 0 | AN30: 0 | AO30: 0 | AP30: 1 | AQ30: 0 | AR30: 0 | AS30: 1 | AT30: 0 | AU30: 0 | AV30: 0 | AW30: 0 | AX30: 0 | AY30: 0 | AZ30: 0 | BA30: 0 | BB30: 0 | BC30: 0 | BD30: 0 | BE30: 0 | BF30: 0 | BG30: 0 | BH30: 0 | BI30: 0 | BJ30: 0 | BK30: 35 | BL30: 210 | BM30: =SUM(BK30:BL30) -> 245 | BN30: PUNCAK HARAPAN | BO30: =BK30/$BM30 -> 0.14285714 | BP30: =BL30/$BM30 -> 0.85714286
A31: 74.08.03.2020 | B31: 99 | C31: 94 | D31: 193 | E31: 6 | F31: 2 | G31: 74 | H31: 32 | I31: 62 | J31: 7 | K31: 0 | L31: 10 | M31: 0 | N31: 0 | O31: 93 | P31: 0 | Q31: 5 | R31: 62 | S31: 12 | T31: 0 | U31: 3 | V31: 0 | W31: 0 | X31: 3 | Y31: 0 | Z31: 0 | AA31: 2 | AB31: 1 | AC31: 0 | AD31: 1 | AE31: 0 | AF31: 1 | AG31: 0 | AH31: 0 | AI31: 0 | AJ31: 0 | AK31: 0 | AL31: 0 | AM31: 0 | AN31: 4 | AO31: 0 | AP31: 0 | AQ31: 1 | AR31: 0 | AS31: 0 | AT31: 0 | AU31: 0 | AV31: 0 | AW31: 0 | AX31: 0 | AY31: 1 | AZ31: 0 | BA31: 1 | BB31: 0 | BC31: 0 | BD31: 0 | BE31: 0 | BF31: 0 | BG31: 1 | BH31: 0 | BI31: 2 | BJ31: 0 | BK31: 10 | BL31: 183 | BM31: =SUM(BK31:BL31) -> 193 | BN31: TETEBAWO | BO31: =BK31/$BM31 -> 0.051813472 | BP31: =BL31/$BM31 -> 0.94818653
A32: 74.08.03.2021 | B32: 182 | C32: 206 | D32: 388 | E32: 34 | F32: 3 | G32: 87 | H32: 47 | I32: 144 | J32: 0 | K32: 1 | L32: 71 | M32: 1 | N32: 0 | O32: 211 | P32: 0 | Q32: 10 | R32: 64 | S32: 22 | T32: 0 | U32: 8 | V32: 0 | W32: 10 | X32: 2 | Y32: 21 | Z32: 2 | AA32: 0 | AB32: 6 | AC32: 2 | AD32: 3 | AE32: 0 | AF32: 1 | AG32: 0 | AH32: 0 | AI32: 3 | AJ32: 1 | AK32: 1 | AL32: 0 | AM32: 1 | AN32: 2 | AO32: 0 | AP32: 0 | AQ32: 2 | AR32: 0 | AS32: 6 | AT32: 0 | AU32: 3 | AV32: 1 | AW32: 0 | AX32: 0 | AY32: 1 | AZ32: 0 | BA32: 2 | BB32: 1 | BC32: 0 | BD32: 0 | BE32: 0 | BF32: 0 | BG32: 0 | BH32: 0 | BI32: 0 | BJ32: 2 | BK32: 88 | BL32: 300 | BM32: =SUM(BK32:BL32) -> 388 | BN32: MAKKUASENG | BO32: =BK32/$BM32 -> 0.22680412 | BP32: =BL32/$BM32 -> 0.77319588
O33: =SUM(O22:O32) -> 2697 | P33: =SUM(P22:P32) -> 3 | Q33: =SUM(Q22:Q32) -> 91 | R33: =SUM(R22:R32) -> 1631 | S33: =SUM(S22:S32) -> 127 | T33: =SUM(T22:T32) -> 2 | U33: =SUM(U22:U32) -> 171 | V33: =SUM(V22:V32) -> 0 | ... BJ33: =SUM(BJ22:BJ32) -> 2 | BM33: =SUM(BK33:BL33) -> 0
B36: Nama Deskel | C36: pemilih_dpt_j | D36: total
B37: BATU PUTIH | C37: 1117 | D37: 1080
B38: LATOWU | C38: 906 | D38: 795
B39: MOSIKU | C39: 813 | D39: 732
B40: LELEWAWO | C40: 895 | D40: 836 | Q40: =_xlfn.XLOOKUP(R40,$S$14:$AJ$14,$S$2:$AJ$2) -> Partai Kebangkitan Bangsa | R40: {=TRANSPOSE(S14:AJ14)} -> 492 | S40: =RANK(R40,$R$40:$R$57) -> 3 | U40: {=_xlfn._xlws.SORT(Q40:S57,3)} -> Partai Gerakan Indonesia Raya | V40: 1548 | W40: 1 | Z40: Partai Gerakan Indonesia Raya
B41: BATU API | C41: 149 | D41: 144 | Q41: =_xlfn.XLOOKUP(R41,$S$14:$AJ$14,$S$2:$AJ$2) -> Partai Gerakan Indonesia Raya | R41: 1548 | S41: =RANK(R41,$R$40:$R$57) -> 1 | U41: Partai Demokrat | V41: 1476 | W41: 2 | Z41: Partai Demokrat
B42: BUKIT TINGGI | C42: 498 | D42: 413 | Q42: =_xlfn.XLOOKUP(R42,$S$14:$AJ$14,$S$2:$AJ$2) -> Partai Demokrasi Indonesia Perjuangan | R42: 400 | S42: =RANK(R42,$R$40:$R$57) -> 4 | U42: Partai Kebangkitan Bangsa | V42: 492 | W42: 3 | Z42: Partai Kebangkitan Bangsa
B43: BUKIT BARU | C43: 393 | D43: 337 | Q43: =_xlfn.XLOOKUP(R43,$S$14:$AJ$14,$S$2:$AJ$2) -> Partai Golongan Karya | R43: 170 | S43: =RANK(R43,$R$40:$R$57) -> 8 | U43: Partai Demokrasi Indonesia Perjuangan | V43: 400 | W43: 4 | Z43: Partai Demokrasi Indonesia Perjuangan
B44: PARUNG LAMPE | C44: 204 | D44: 168 | Q44: =_xlfn.XLOOKUP(R44,$S$14:$AJ$14,$S$2:$AJ$2) -> Partai NasDem | R44: 255 | S44: =RANK(R44,$R$40:$R$57) -> 5 | U44: Partai NasDem | V44: 255 | W44: 5 | Z44: Partai NasDem
B45: PUNCAK HARAPAN | C45: 264 | D45: 245 | Q45: =_xlfn.XLOOKUP(R45,$S$14:$AJ$14,$S$2:$AJ$2) -> Partai Buruh | R45: 28 | S45: =RANK(R45,$R$40:$R$57) -> 11 | U45: Partai Persatuan Pembangunan | V45: 247 | W45: 6
B46: TETEBAWO | C46: 288 | D46: 193 | Q46: =_xlfn.XLOOKUP(R46,$S$14:$AJ$14,$S$2:$AJ$2) -> Partai Gelombang Rakyat Indonesia | R46: 17 | S46: =RANK(R46,$R$40:$R$57) -> 12 | U46: Partai Keadilan Sejahtera | V46: 208 | W46: 7
B47: MAKKUASENG | C47: 436 | D47: 388 | Q47: =_xlfn.XLOOKUP(R47,$S$14:$AJ$14,$S$2:$AJ$2) -> Partai Keadilan Sejahtera | R47: 208 | S47: =RANK(R47,$R$40:$R$57) -> 7 | U47: Partai Golongan Karya | V47: 170 | W47: 8
Q48: =_xlfn.XLOOKUP(R48,$S$14:$AJ$14,$S$2:$AJ$2) -> Partai Kebangkitan Nusantara | R48: 7 | S48: =RANK(R48,$R$40:$R$57) -> 16 | U48: Partai Bulan Bintang | V48: 114 | W48: 9
...

Sheet pendidikan
A2: 74.08.03.1001 | B2: =SUM(Sheet1!E22:F22) -> 132 | C2: =Sheet1!G22 -> 254 | D2: =Sheet1!H22 -> 162 | E2: =SUM(Sheet1!I22:J22) -> 356 | F2: =SUM(Sheet1!K22:L22) -> 171 | G2: =SUM(Sheet1!M22:N22) -> 5 | H2: =SUM(B2:G2) -> 1080
A3: 74.08.03.2002 | B3: =SUM(Sheet1!E23:F23) -> 60 | C3: =Sheet1!G23 -> 225 | D3: =Sheet1!H23 -> 132 | E3: =SUM(Sheet1!I23:J23) -> 290 | F3: =SUM(Sheet1!K23:L23) -> 88 | G3: =SUM(Sheet1!M23:N23) -> 0 | H3: =SUM(B3:G3) -> 795
A4: 74.08.03.2003 | B4: =SUM(Sheet1!E24:F24) -> 34 | C4: =Sheet1!G24 -> 209 | D4: =Sheet1!H24 -> 173 | E4: =SUM(Sheet1!I24:J24) -> 268 | F4: =SUM(Sheet1!K24:L24) -> 47 | G4: =SUM(Sheet1!M24:N24) -> 1 | H4: =SUM(B4:G4) -> 732
A5: 74.08.03.2004 | B5: =SUM(Sheet1!E25:F25) -> 68 | C5: =Sheet1!G25 -> 269 | D5: =Sheet1!H25 -> 121 | E5: =SUM(Sheet1!I25:J25) -> 276 | F5: =SUM(Sheet1!K25:L25) -> 101 | G5: =SUM(Sheet1!M25:N25) -> 1 | H5: =SUM(B5:G5) -> 836
A6: 74.08.03.2011 | B6: =SUM(Sheet1!E26:F26) -> 34 | C6: =Sheet1!G26 -> 32 | D6: =Sheet1!H26 -> 19 | E6: =SUM(Sheet1!I26:J26) -> 44 | F6: =SUM(Sheet1!K26:L26) -> 15 | G6: =SUM(Sheet1!M26:N26) -> 0 | H6: =SUM(B6:G6) -> 144
A7: 74.08.03.2012 | B7: =SUM(Sheet1!E27:F27) -> 64 | C7: =Sheet1!G27 -> 144 | D7: =Sheet1!H27 -> 68 | E7: =SUM(Sheet1!I27:J27) -> 112 | F7: =SUM(Sheet1!K27:L27) -> 25 | G7: =SUM(Sheet1!M27:N27) -> 0 | H7: =SUM(B7:G7) -> 413
A8: 74.08.03.2015 | B8: =SUM(Sheet1!E28:F28) -> 54 | C8: =Sheet1!G28 -> 171 | D8: =Sheet1!H28 -> 34 | E8: =SUM(Sheet1!I28:J28) -> 65 | F8: =SUM(Sheet1!K28:L28) -> 13 | G8: =SUM(Sheet1!M28:N28) -> 0 | H8: =SUM(B8:G8) -> 337
A9: 74.08.03.2016 | B9: =SUM(Sheet1!E29:F29) -> 33 | C9: =Sheet1!G29 -> 46 | D9: =Sheet1!H29 -> 29 | E9: =SUM(Sheet1!I29:J29) -> 47 | F9: =SUM(Sheet1!K29:L29) -> 13 | G9: =SUM(Sheet1!M29:N29) -> 0 | H9: =SUM(B9:G9) -> 168
A10: 74.08.03.2017 | B10: =SUM(Sheet1!E30:F30) -> 66 | C10: =Sheet1!G30 -> 83 | D10: =Sheet1!H30 -> 30 | E10: =SUM(Sheet1!I30:J30) -> 46 | F10: =SUM(Sheet1!K30:L30) -> 20 | G10: =SUM(Sheet1!M30:N30) -> 0 | H10: =SUM(B10:G10) -> 245
A11: 74.08.03.2020 | B11: =SUM(Sheet1!E31:F31) -> 8 | C11: =Sheet1!G31 -> 74 | D11: =Sheet1!H31 -> 32 | E11: =SUM(Sheet1!I31:J31) -> 69 | F11: =SUM(Sheet1!K31:L31) -> 10 | G11: =SUM(Sheet1!M31:N31) -> 0 | H11: =SUM(B11:G11) -> 193
A12: 74.08.03.2021 | B12: =SUM(Sheet1!E32:F32) -> 37 | C12: =Sheet1!G32 -> 87 | D12: =Sheet1!H32 -> 47 | E12: =SUM(Sheet1!I32:J32) -> 144 | F12: =SUM(Sheet1!K32:L32) -> 72 | G12: =SUM(Sheet1!M32:N32) -> 1 | H12: =SUM(B12:G12) -> 388
B14: Tidak Punya Ijazah | C14: SD/sederajat | D14: SMP/sederajat | E14: SMA/sederajat | F14: D1-S1 | G14: S2-S3
A15: BATU PUTIH | B15: =B2/$H2 -> 0.12222222 | C15: =C2/$H2 -> 0.23518519 | D15: =D2/$H2 -> 0.15 | E15: =E2/$H2 -> 0.32962963 | F15: =F2/$H2 -> 0.15833333 | G15: =G2/$H2 -> 0.0046296296
A16: LATOWU | B16: =B3/$H3 -> 0.075471698 | C16: =C3/$H3 -> 0.28301887 | D16: =D3/$H3 -> 0.16603774 | E16: =E3/$H3 -> 0.36477987 | F16: =F3/$H3 -> 0.11069182 | G16: =G3/$H3 -> 0
A17: MOSIKU | B17: =B4/$H4 -> 0.046448087 | C17: =C4/$H4 -> 0.28551913 | D17: =D4/$H4 -> 0.2363388 | E17: =E4/$H4 -> 0.36612022 | F17: =F4/$H4 -> 0.06420765 | G17: =G4/$H4 -> 0.0013661202
A18: LELEWAWO | B18: =B5/$H5 -> 0.081339713 | C18: =C5/$H5 -> 0.32177033 | D18: =D5/$H5 -> 0.14473684 | E18: =E5/$H5 -> 0.33014354 | F18: =F5/$H5 -> 0.1208134 | G18: =G5/$H5 -> 0.0011961722
A19: BATU API | B19: =B6/$H6 -> 0.23611111 | C19: =C6/$H6 -> 0.22222222 | D19: =D6/$H6 -> 0.13194444 | E19: =E6/$H6 -> 0.30555556 | F19: =F6/$H6 -> 0.10416667 | G19: =G6/$H6 -> 0
A20: BUKIT TINGGI | B20: =B7/$H7 -> 0.15496368 | C20: =C7/$H7 -> 0.34866828 | D20: =D7/$H7 -> 0.16464891 | E20: =E7/$H7 -> 0.27118644 | F20: =F7/$H7 -> 0.060532688 | G20: =G7/$H7 -> 0
A21: BUKIT BARU | B21: =B8/$H8 -> 0.16023739 | C21: =C8/$H8 -> 0.5074184 | D21: =D8/$H8 -> 0.10089021 | E21: =E8/$H8 -> 0.19287834 | F21: =F8/$H8 -> 0.038575668 | G21: =G8/$H8 -> 0
A22: PARUNG LAMPE | B22: =B9/$H9 -> 0.19642857 | C22: =C9/$H9 -> 0.27380952 | D22: =D9/$H9 -> 0.17261905 | E22: =E9/$H9 -> 0.2797619 | F22: =F9/$H9 -> 0.077380952 | G22: =G9/$H9 -> 0
A23: PUNCAK HARAPAN | B23: =B10/$H10 -> 0.26938776 | C23: =C10/$H10 -> 0.33877551 | D23: =D10/$H10 -> 0.12244898 | E23: =E10/$H10 -> 0.1877551 | F23: =F10/$H10 -> 0.081632653 | G23: =G10/$H10 -> 0
A24: TETEBAWO | B24: =B11/$H11 -> 0.041450777 | C24: =C11/$H11 -> 0.38341969 | D24: =D11/$H11 -> 0.16580311 | E24: =E11/$H11 -> 0.35751295 | F24: =F11/$H11 -> 0.051813472 | G24: =G11/$H11 -> 0
A25: MAKKUASENG | B25: =B12/$H12 -> 0.095360825 | C25: =C12/$H12 -> 0.2242268 | D25: =D12/$H12 -> 0.12113402 | E25: =E12/$H12 -> 0.37113402 | F25: =F12/$H12 -> 0.18556701 | G25: =G12/$H12 -> 0.0025773196

Sheet ppwp dan top 5 parpol
D4: Partai Gerakan Indonesia Raya | E4: Partai Demokrat | F4: Partai Kebangkitan Bangsa | G4: Partai Demokrasi Indonesia Perjuangan | H4: Partai NasDem | M4: PPWP 01 | N4: PPWP 02 | O4: PPWP 03
C5: 74.08.03.1001 | D5: =INDEX(Sheet1!$S$3:$AJ$13,MATCH($C5,Sheet1!$A$3:$A$13,0),MATCH(D$4,Sheet1!$S$2:$AJ$2,0)) -> 264 | E5: =INDEX(Sheet1!$S$3:$AJ$13,MATCH($C5,Sheet1!$A$3:$A$13,0),MATCH(E$4,Sheet1!$S$2:$AJ$2,0)) -> 371 | F5: =INDEX(Sheet1!$S$3:$AJ$13,MATCH($C5,Sheet1!$A$3:$A$13,0),MATCH(F$4,Sheet1!$S$2:$AJ$2,0)) -> 76 | G5: =INDEX(Sheet1!$S$3:$AJ$13,MATCH($C5,Sheet1!$A$3:$A$13,0),MATCH(G$4,Sheet1!$S$2:$AJ$2,0)) -> 41 | H5: =INDEX(Sheet1!$S$3:$AJ$13,MATCH($C5,Sheet1!$A$3:$A$13,0),MATCH(H$4,Sheet1!$S$2:$AJ$2,0)) -> 39 | I5: {=Sheet1!AK3:AK13} -> 940 | L5: BATU PUTIH | M5: 371 | N5: 593 | O5: 19 | P5: =SUM(M5:O5) -> 983
C6: 74.08.03.2002 | D6: =INDEX(Sheet1!$S$3:$AJ$13,MATCH($C6,Sheet1!$A$3:$A$13,0),MATCH(D$4,Sheet1!$S$2:$AJ$2,0)) -> 193 | E6: =INDEX(Sheet1!$S$3:$AJ$13,MATCH($C6,Sheet1!$A$3:$A$13,0),MATCH(E$4,Sheet1!$S$2:$AJ$2,0)) -> 278 | F6: =INDEX(Sheet1!$S$3:$AJ$13,MATCH($C6,Sheet1!$A$3:$A$13,0),MATCH(F$4,Sheet1!$S$2:$AJ$2,0)) -> 76 | G6: =INDEX(Sheet1!$S$3:$AJ$13,MATCH($C6,Sheet1!$A$3:$A$13,0),MATCH(G$4,Sheet1!$S$2:$AJ$2,0)) -> 66 | H6: =INDEX(Sheet1!$S$3:$AJ$13,MATCH($C6,Sheet1!$A$3:$A$13,0),MATCH(H$4,Sheet1!$S$2:$AJ$2,0)) -> 49 | I6: 786 | L6: LATOWU | M6: 332 | N6: 460 | O6: 15 | P6: =SUM(M6:O6) -> 807
C7: 74.08.03.2003 | D7: =INDEX(Sheet1!$S$3:$AJ$13,MATCH($C7,Sheet1!$A$3:$A$13,0),MATCH(D$4,Sheet1!$S$2:$AJ$2,0)) -> 315 | E7: =INDEX(Sheet1!$S$3:$AJ$13,MATCH($C7,Sheet1!$A$3:$A$13,0),MATCH(E$4,Sheet1!$S$2:$AJ$2,0)) -> 128 | F7: =INDEX(Sheet1!$S$3:$AJ$13,MATCH($C7,Sheet1!$A$3:$A$13,0),MATCH(F$4,Sheet1!$S$2:$AJ$2,0)) -> 38 | G7: =INDEX(Sheet1!$S$3:$AJ$13,MATCH($C7,Sheet1!$A$3:$A$13,0),MATCH(G$4,Sheet1!$S$2:$AJ$2,0)) -> 53 | H7: =INDEX(Sheet1!$S$3:$AJ$13,MATCH($C7,Sheet1!$A$3:$A$13,0),MATCH(H$4,Sheet1!$S$2:$AJ$2,0)) -> 25 | I7: 667 | L7: MOSIKU | M7: 123 | N7: 554 | O7: 13 | P7: =SUM(M7:O7) -> 690
C8: 74.08.03.2004 | D8: =INDEX(Sheet1!$S$3:$AJ$13,MATCH($C8,Sheet1!$A$3:$A$13,0),MATCH(D$4,Sheet1!$S$2:$AJ$2,0)) -> 211 | E8: =INDEX(Sheet1!$S$3:$AJ$13,MATCH($C8,Sheet1!$A$3:$A$13,0),MATCH(E$4,Sheet1!$S$2:$AJ$2,0)) -> 196 | F8: =INDEX(Sheet1!$S$3:$AJ$13,MATCH($C8,Sheet1!$A$3:$A$13,0),MATCH(F$4,Sheet1!$S$2:$AJ$2,0)) -> 50 | G8: =INDEX(Sheet1!$S$3:$AJ$13,MATCH($C8,Sheet1!$A$3:$A$13,0),MATCH(G$4,Sheet1!$S$2:$AJ$2,0)) -> 41 | H8: =INDEX(Sheet1!$S$3:$AJ$13,MATCH($C8,Sheet1!$A$3:$A$13,0),MATCH(H$4,Sheet1!$S$2:$AJ$2,0)) -> 73 | I8: 787 | L8: LELEWAWO | M8: 301 | N8: 525 | O8: 9 | P8: =SUM(M8:O8) -> 835
C9: 74.08.03.2011 | D9: =INDEX(Sheet1!$S$3:$AJ$13,MATCH($C9,Sheet1!$A$3:$A$13,0),MATCH(D$4,Sheet1!$S$2:$AJ$2,0)) -> 15 | E9: =INDEX(Sheet1!$S$3:$AJ$13,MATCH($C9,Sheet1!$A$3:$A$13,0),MATCH(E$4,Sheet1!$S$2:$AJ$2,0)) -> 78 | F9: =INDEX(Sheet1!$S$3:$AJ$13,MATCH($C9,Sheet1!$A$3:$A$13,0),MATCH(F$4,Sheet1!$S$2:$AJ$2,0)) -> 6 | G9: =INDEX(Sheet1!$S$3:$AJ$13,MATCH($C9,Sheet1!$A$3:$A$13,0),MATCH(G$4,Sheet1!$S$2:$AJ$2,0)) -> 0 | H9: =INDEX(Sheet1!$S$3:$AJ$13,MATCH($C9,Sheet1!$A$3:$A$13,0),MATCH(H$4,Sheet1!$S$2:$AJ$2,0)) -> 3 | I9: 114 | L9: BATU API | M9: 59 | N9: 55 | O9: 2 | P9: =SUM(M9:O9) -> 116
C10: 74.08.03.2012 | D10: =INDEX(Sheet1!$S$3:$AJ$13,MATCH($C10,Sheet1!$A$3:$A$13,0),MATCH(D$4,Sheet1!$S$2:$AJ$2,0)) -> 205 | E10: =INDEX(Sheet1!$S$3:$AJ$13,MATCH($C10,Sheet1!$A$3:$A$13,0),MATCH(E$4,Sheet1!$S$2:$AJ$2,0)) -> 39 | F10: =INDEX(Sheet1!$S$3:$AJ$13,MATCH($C10,Sheet1!$A$3:$A$13,0),MATCH(F$4,Sheet1!$S$2:$AJ$2,0)) -> 85 | G10: =INDEX(Sheet1!$S$3:$AJ$13,MATCH($C10,Sheet1!$A$3:$A$13,0),MATCH(G$4,Sheet1!$S$2:$AJ$2,0)) -> 46 | H10: =INDEX(Sheet1!$S$3:$AJ$13,MATCH($C10,Sheet1!$A$3:$A$13,0),MATCH(H$4,Sheet1!$S$2:$AJ$2,0)) -> 19 | I10: 424 | L10: BUKIT TINGGI | M10: 147 | N10: 278 | O10: 26 | P10: =SUM(M10:O10) -> 451
C11: 74.08.03.2015 | D11: =INDEX(Sheet1!$S$3:$AJ$13,MATCH($C11,Sheet1!$A$3:$A$13,0),MATCH(D$4,Sheet1!$S$2:$AJ$2,0)) -> 94 | E11: =INDEX(Sheet1!$S$3:$AJ$13,MATCH($C11,Sheet1!$A$3:$A$13,0),MATCH(E$4,Sheet1!$S$2:$AJ$2,0)) -> 49 | F11: =INDEX(Sheet1!$S$3:$AJ$13,MATCH($C11,Sheet1!$A$3:$A$13,0),MATCH(F$4,Sheet1!$S$2:$AJ$2,0)) -> 48 | G11: =INDEX(Sheet1!$S$3:$AJ$13,MATCH($C11,Sheet1!$A$3:$A$13,0),MATCH(G$4,Sheet1!$S$2:$AJ$2,0)) -> 104 | H11: =INDEX(Sheet1!$S$3:$AJ$13,MATCH($C11,Sheet1!$A$3:$A$13,0),MATCH(H$4,Sheet1!$S$2:$AJ$2,0)) -> 4 | I11: 327 | L11: BUKIT BARU | M11: 108 | N11: 220 | O11: 14 | P11: =SUM(M11:O11) -> 342
C12: 74.08.03.2016 | D12: =INDEX(Sheet1!$S$3:$AJ$13,MATCH($C12,Sheet1!$A$3:$A$13,0),MATCH(D$4,Sheet1!$S$2:$AJ$2,0)) -> 46 | E12: =INDEX(Sheet1!$S$3:$AJ$13,MATCH($C12,Sheet1!$A$3:$A$13,0),MATCH(E$4,Sheet1!$S$2:$AJ$2,0)) -> 71 | F12: =INDEX(Sheet1!$S$3:$AJ$13,MATCH($C12,Sheet1!$A$3:$A$13,0),MATCH(F$4,Sheet1!$S$2:$AJ$2,0)) -> 37 | G12: =INDEX(Sheet1!$S$3:$AJ$13,MATCH($C12,Sheet1!$A$3:$A$13,0),MATCH(G$4,Sheet1!$S$2:$AJ$2,0)) -> 6 | H12: =INDEX(Sheet1!$S$3:$AJ$13,MATCH($C12,Sheet1!$A$3:$A$13,0),MATCH(H$4,Sheet1!$S$2:$AJ$2,0)) -> 4 | I12: 173 | L12: PARUNG LAMPE | M12: 82 | N12: 92 | O12: 2 | P12: =SUM(M12:O12) -> 176
C13: 74.08.03.2017 | D13: =INDEX(Sheet1!$S$3:$AJ$13,MATCH($C13,Sheet1!$A$3:$A$13,0),MATCH(D$4,Sheet1!$S$2:$AJ$2,0)) -> 110 | E13: =INDEX(Sheet1!$S$3:$AJ$13,MATCH($C13,Sheet1!$A$3:$A$13,0),MATCH(E$4,Sheet1!$S$2:$AJ$2,0)) -> 79 | F13: =INDEX(Sheet1!$S$3:$AJ$13,MATCH($C13,Sheet1!$A$3:$A$13,0),MATCH(F$4,Sheet1!$S$2:$AJ$2,0)) -> 16 | G13: =INDEX(Sheet1!$S$3:$AJ$13,MATCH($C13,Sheet1!$A$3:$A$13,0),MATCH(G$4,Sheet1!$S$2:$AJ$2,0)) -> 6 | H13: =INDEX(Sheet1!$S$3:$AJ$13,MATCH($C13,Sheet1!$A$3:$A$13,0),MATCH(H$4,Sheet1!$S$2:$AJ$2,0)) -> 2 | I13: 229 | L13: PUNCAK HARAPAN | M13: 98 | N13: 127 | O13: 5 | P13: =SUM(M13:O13) -> 230
C14: 74.08.03.2020 | D14: =INDEX(Sheet1!$S$3:$AJ$13,MATCH($C14,Sheet1!$A$3:$A$13,0),MATCH(D$4,Sheet1!$S$2:$AJ$2,0)) -> 29 | E14: =INDEX(Sheet1!$S$3:$AJ$13,MATCH($C14,Sheet1!$A$3:$A$13,0),MATCH(E$4,Sheet1!$S$2:$AJ$2,0)) -> 114 | F14: =INDEX(Sheet1!$S$3:$AJ$13,MATCH($C14,Sheet1!$A$3:$A$13,0),MATCH(F$4,Sheet1!$S$2:$AJ$2,0)) -> 10 | G14: =INDEX(Sheet1!$S$3:$AJ$13,MATCH($C14,Sheet1!$A$3:$A$13,0),MATCH(G$4,Sheet1!$S$2:$AJ$2,0)) -> 14 | H14: =INDEX(Sheet1!$S$3:$AJ$13,MATCH($C14,Sheet1!$A$3:$A$13,0),MATCH(H$4,Sheet1!$S$2:$AJ$2,0)) -> 3 | I14: 237 | L14: TETEBAWO | M14: 48 | N14: 194 | O14: 2 | P14: =SUM(M14:O14) -> 244
C15: 74.08.03.2021 | D15: =INDEX(Sheet1!$S$3:$AJ$13,MATCH($C15,Sheet1!$A$3:$A$13,0),MATCH(D$4,Sheet1!$S$2:$AJ$2,0)) -> 66 | E15: =INDEX(Sheet1!$S$3:$AJ$13,MATCH($C15,Sheet1!$A$3:$A$13,0),MATCH(E$4,Sheet1!$S$2:$AJ$2,0)) -> 73 | F15: =INDEX(Sheet1!$S$3:$AJ$13,MATCH($C15,Sheet1!$A$3:$A$13,0),MATCH(F$4,Sheet1!$S$2:$AJ$2,0)) -> 50 | G15: =INDEX(Sheet1!$S$3:$AJ$13,MATCH($C15,Sheet1!$A$3:$A$13,0),MATCH(G$4,Sheet1!$S$2:$AJ$2,0)) -> 23 | H15: =INDEX(Sheet1!$S$3:$AJ$13,MATCH($C15,Sheet1!$A$3:$A$13,0),MATCH(H$4,Sheet1!$S$2:$AJ$2,0)) -> 34 | I15: 357 | L15: MAKKUASENG | M15: 102 | N15: 259 | O15: 3 | P15: =SUM(M15:O15) -> 364
D19: Partai Gerakan Indonesia Raya | E19: Partai Demokrat | F19: Partai Kebangkitan Bangsa | G19: Partai Demokrasi Indonesia Perjuangan | H19: Partai NasDem | M19: PPWP 01 | N19: PPWP 02 | O19: PPWP 03
C20: BATU PUTIH | D20: =D5/$I5 -> 0.28085106 | E20: =E5/$I5 -> 0.39468085 | F20: =F5/$I5 -> 0.080851064 | G20: =G5/$I5 -> 0.043617021 | H20: =H5/$I5 -> 0.041489362 | L20: BATU PUTIH | M20: =M5/$P5 -> 0.37741607 | N20: =N5/$P5 -> 0.60325534 | O20: =O5/$P5 -> 0.019328586
C21: LATOWU | D21: =D6/$I6 -> 0.24554707 | E21: =E6/$I6 -> 0.35368957 | F21: =F6/$I6 -> 0.096692112 | G21: =G6/$I6 -> 0.083969466 | H21: =H6/$I6 -> 0.062340967 | L21: LATOWU | M21: =M6/$P6 -> 0.41140025 | N21: =N6/$P6 -> 0.57001239 | O21: =O6/$P6 -> 0.018587361
C22: MOSIKU | D22: =D7/$I7 -> 0.47226387 | E22: =E7/$I7 -> 0.19190405 | F22: =F7/$I7 -> 0.056971514 | G22: =G7/$I7 -> 0.07946027 | H22: =H7/$I7 -> 0.037481259 | L22: MOSIKU | M22: =M7/$P7 -> 0.17826087 | N22: =N7/$P7 -> 0.80289855 | O22: =O7/$P7 -> 0.01884058
C23: LELEWAWO | D23: =D8/$I8 -> 0.26810673 | E23: =E8/$I8 -> 0.24904701 | F23: =F8/$I8 -> 0.063532402 | G23: =G8/$I8 -> 0.052096569 | H23: =H8/$I8 -> 0.092757306 | L23: LELEWAWO | M23: =M8/$P8 -> 0.36047904 | N23: =N8/$P8 -> 0.62874251 | O23: =O8/$P8 -> 0.010778443
C24: BATU API | D24: =D9/$I9 -> 0.13157895 | E24: =E9/$I9 -> 0.68421053 | F24: =F9/$I9 -> 0.052631579 | G24: =G9/$I9 -> 0 | H24: =H9/$I9 -> 0.026315789 | L24: BATU API | M24: =M9/$P9 -> 0.50862069 | N24: =N9/$P9 -> 0.47413793 | O24: =O9/$P9 -> 0.017241379
C25: BUKIT TINGGI | D25: =D10/$I10 -> 0.48349057 | E25: =E10/$I10 -> 0.091981132 | F25: =F10/$I10 -> 0.2004717 | G25: =G10/$I10 -> 0.10849057 | H25: =H10/$I10 -> 0.044811321 | L25: BUKIT TINGGI | M25: =M10/$P10 -> 0.32594235 | N25: =N10/$P10 -> 0.61640798 | O25: =O10/$P10 -> 0.057649667
C26: BUKIT BARU | D26: =D11/$I11 -> 0.28746177 | E26: =E11/$I11 -> 0.14984709 | F26: =F11/$I11 -> 0.14678899 | G26: =G11/$I11 -> 0.31804281 | H26: =H11/$I11 -> 0.012232416 | L26: BUKIT BARU | M26: =M11/$P11 -> 0.31578947 | N26: =N11/$P11 -> 0.64327485 | O26: =O11/$P11 -> 0.040935673
C27: PARUNG LAMPE | D27: =D12/$I12 -> 0.26589595 | E27: =E12/$I12 -> 0.41040462 | F27: =F12/$I12 -> 0.21387283 | G27: =G12/$I12 -> 0.034682081 | H27: =H12/$I12 -> 0.023121387 | L27: PARUNG LAMPE | M27: =M12/$P12 -> 0.46590909 | N27: =N12/$P12 -> 0.52272727 | O27: =O12/$P12 -> 0.011363636
C28: PUNCAK HARAPAN | D28: =D13/$I13 -> 0.48034934 | E28: =E13/$I13 -> 0.34497817 | F28: =F13/$I13 -> 0.069868996 | G28: =G13/$I13 -> 0.026200873 | H28: =H13/$I13 -> 0.0087336245 | L28: PUNCAK HARAPAN | M28: =M13/$P13 -> 0.42608696 | N28: =N13/$P13 -> 0.55217391 | O28: =O13/$P13 -> 0.02173913
C29: TETEBAWO | D29: =D14/$I14 -> 0.12236287 | E29: =E14/$I14 -> 0.48101266 | F29: =F14/$I14 -> 0.042194093 | G29: =G14/$I14 -> 0.05907173 | H29: =H14/$I14 -> 0.012658228 | L29: TETEBAWO | M29: =M14/$P14 -> 0.19672131 | N29: =N14/$P14 -> 0.79508197 | O29: =O14/$P14 -> 0.0081967213
C30: MAKKUASENG | D30: =D15/$I15 -> 0.18487395 | E30: =E15/$I15 -> 0.20448179 | F30: =F15/$I15 -> 0.14005602 | G30: =G15/$I15 -> 0.06442577 | H30: =H15/$I15 -> 0.095238095 | L30: MAKKUASENG | M30: =M15/$P15 -> 0.28021978 | N30: =N15/$P15 -> 0.71153846 | O30: =O15/$P15 -> 0.0082417582

Sheet pekerjaan dominan
B4: {=TRANSPOSE(Sheet1!O21:BJ33)} -> belum/tidak bekerja | C4: 562 | D4: 483 | E4: 332 | F4: 409 | G4: 68 | H4: 193 | I4: 182 | J4: 78 | K4: 86 | L4: 93 | M4: 211 | N4: 2697
B5: koki/barista/bartender | C5: 2 | D5: 0 | E5: 1 | F5: 0 | G5: 0 | H5: 0 | I5: 0 | J5: 0 | K5: 0 | L5: 0 | M5: 0 | N5: 3 | O5: =RANK(N5,$N$5:$N$51) -> 26 | R5: {=_xlfn._xlws.SORT(B5:O51,12,-1)} -> petani/pekebun | S5: 266 | T5: 152 | U5: 287 | V5: 273 | W5: 39 | X5: 160 | Y5: 144 | Z5: 61 | AA5: 123 | AB5: 62 | AC5: 64 | AD5: 1631 | AE5: 1
B6: pekerja serabutan | C6: 18 | D6: 34 | E6: 7 | F6: 6 | G6: 4 | H6: 5 | I6: 1 | J6: 1 | K6: 0 | L6: 5 | M6: 10 | N6: 91 | O6: =RANK(N6,$N$5:$N$51) -> 4 | R6: wirausaha | S6: 43 | T6: 16 | U6: 4 | V6: 13 | W6: 4 | X6: 9 | Y6: 0 | Z6: 2 | AA6: 2 | AB6: 12 | AC6: 22 | AD6: 127 | AE6: 3
B7: petani/pekebun | C7: 266 | D7: 152 | E7: 287 | F7: 273 | G7: 39 | H7: 160 | I7: 144 | J7: 61 | K7: 123 | L7: 62 | M7: 64 | N7: 1631 | O7: =RANK(N7,$N$5:$N$51) -> 1 | R7: tenaga administrasi (tata usaha) | S7: 14 | T7: 5 | U7: 5 | V7: 7 | W7: 1 | X7: 1 | Y7: 1 | Z7: 0 | AA7: 1 | AB7: 0 | AC7: 21 | AD7: 56 | AE7: 7
B8: wirausaha | C8: 43 | D8: 16 | E8: 4 | F8: 13 | G8: 4 | H8: 9 | I8: 0 | J8: 2 | K8: 2 | L8: 12 | M8: 22 | N8: 127 | O8: =RANK(N8,$N$5:$N$51) -> 3 | R8: pekerja serabutan | S8: 18 | T8: 34 | U8: 7 | V8: 6 | W8: 4 | X8: 5 | Y8: 1 | Z8: 1 | AA8: 0 | AB8: 5 | AC8: 10 | AD8: 91 | AE8: 4
B9: ustadz/mubaligh | C9: 2 | D9: 0 | E9: 0 | F9: 0 | G9: 0 | H9: 0 | I9: 0 | J9: 0 | K9: 0 | L9: 0 | M9: 0 | N9: 2 | O9: =RANK(N9,$N$5:$N$51) -> 28 | R9: buruh industri | S9: 24 | T9: 14 | U9: 10 | V9: 7 | W9: 7 | X9: 5 | Y9: 1 | Z9: 1 | AA9: 1 | AB9: 0 | AC9: 10 | AD9: 80 | AE9: 5
B10: guru/pendidik | C10: 49 | D10: 28 | E10: 20 | F10: 36 | G10: 5 | H10: 6 | I10: 4 | J10: 4 | K10: 8 | L10: 3 | M10: 8 | N10: 171 | O10: =RANK(N10,$N$5:$N$51) -> 2 | R10: guru/pendidik | S10: 49 | T10: 28 | U10: 20 | V10: 36 | W10: 5 | X10: 6 | Y10: 4 | Z10: 4 | AA10: 8 | AB10: 3 | AC10: 8 | AD10: 171 | AE10: 2
B11: polisi | C11: 0 | D11: 0 | E11: 0 | F11: 0 | G11: 0 | H11: 0 | I11: 0 | J11: 0 | K11: 0 | L11: 0 | M11: 0 | N11: 0 | O11: =RANK(N11,$N$5:$N$51) -> 46 | R11: driver/pengemudi | S11: 10 | T11: 12 | U11: 11 | V11: 4 | W11: 1 | X11: 4 | Y11: 0 | Z11: 4 | AA11: 0 | AB11: 1 | AC11: 6 | AD11: 53 | AE11: 8
B12: buruh industri | C12: 24 | D12: 14 | E12: 10 | F12: 7 | G12: 7 | H12: 5 | I12: 1 | J12: 1 | K12: 1 | L12: 0 | M12: 10 | N12: 80 | O12: =RANK(N12,$N$5:$N$51) -> 5 | R12: buruh tani | S12: 4 | T12: 0 | U12: 3 | V12: 0 | W12: 0 | X12: 0 | Y12: 0 | Z12: 1 | AA12: 1 | AB12: 0 | AC12: 6 | AD12: 15 | AE12: 20
B13: pekerja/karyawan swasta | C13: 20 | D13: 9 | E13: 14 | F13: 12 | G13: 0 | H13: 7 | I13: 2 | J13: 1 | K13: 0 | L13: 3 | M13: 2 | N13: 70 | O13: =RANK(N13,$N$5:$N$51) -> 6 | R13: bidan | S13: 15 | T13: 10 | U13: 1 | V13: 4 | W13: 1 | X13: 5 | Y13: 0 | Z13: 0 | AA13: 0 | AB13: 1 | AC13: 3 | AD13: 40 | AE13: 9
B14: tenaga administrasi (tata usaha) | C14: 14 | D14: 5 | E14: 5 | F14: 7 | G14: 1 | H14: 1 | I14: 1 | J14: 0 | K14: 1 | L14: 0 | M14: 21 | N14: 56 | O14: =RANK(N14,$N$5:$N$51) -> 7 | R14: perawat | S14: 6 | T14: 3 | U14: 1 | V14: 2 | W14: 2 | X14: 5 | Y14: 0 | Z14: 0 | AA14: 0 | AB14: 0 | AC14: 3 | AD14: 22 | AE14: 15
B15: montir/mekanik/teknisi | C15: 6 | D15: 3 | E15: 3 | F15: 2 | G15: 2 | H15: 5 | I15: 0 | J15: 1 | K15: 1 | L15: 0 | M15: 2 | N15: 25 | O15: =RANK(N15,$N$5:$N$51) -> 12 | R15: pelayan/penjaga toko | S15: 2 | T15: 0 | U15: 1 | V15: 2 | W15: 0 | X15: 0 | Y15: 0 | Z15: 0 | AA15: 0 | AB15: 0 | AC15: 3 | AD15: 8 | AE15: 23
B16: peternak | C16: 2 | D16: 2 | E16: 1 | F16: 0 | G16: 0 | H16: 1 | I16: 0 | J16: 8 | K16: 1 | L16: 2 | M16: 0 | N16: 17 | O16: =RANK(N16,$N$5:$N$51) -> 18 | R16: pekerja/karyawan swasta | S16: 20 | T16: 9 | U16: 14 | V16: 12 | W16: 0 | X16: 7 | Y16: 2 | Z16: 1 | AA16: 0 | AB16: 3 | AC16: 2 | AD16: 70 | AE16: 6
B17: driver/pengemudi | C17: 10 | D17: 12 | E17: 11 | F17: 4 | G17: 1 | H17: 4 | I17: 0 | J17: 4 | K17: 0 | L17: 1 | M17: 6 | N17: 53 | O17: =RANK(N17,$N$5:$N$51) -> 8 | R17: montir/mekanik/teknisi | S17: 6 | T17: 3 | U17: 3 | V17: 2 | W17: 2 | X17: 5 | Y17: 0 | Z17: 1 | AA17: 1 | AB17: 0 | AC17: 2 | AD17: 25 | AE17: 12
... B51: dokter | C51: 0 | D51: 0 | E51: 0 | F51: 0 | G51: 0 | H51: 0 | I51: 0 | J51: 0 | K51: 0 | L51: 0 | M51: 2 | N51: 2 | O51: =RANK(N51,$N$5:$N$51) -> 28 | R51: kurir | S51: 0 | T51: 0 | U51: 0 | V51: 0 | W51: 0 | X51: 0 | Y51: 0 | Z51: 0 | AA51: 0 | AB51: 2 | AC51: 0 | AD51: 2 | AE51: 28
I57: BATU PUTIH | J57: petani/pekebun, guru/pendidik, wirausaha, buruh industri, pekerja/karyawan swasta
I58: LATOWU | J58: petani/pekebun, pekerja serabutan, guru/pendidik, wirausaha, buruh industri
I59: MOSIKU | J59: petani/pekebun, guru/pendidik, pekerja/karyawan swasta, kontraktor (pemborong), driver/pengemudi
I60: LELEWAWO | J60: petani/pekebun, guru/pendidik, nelayan, operator alat berat, wirausaha
I61: BATU API | J61: petani/pekebun, buruh industri, guru/pendidik, perangkat desa, pekerja serabutan
I62: BUKIT TINGGI | J62: petani/pekebun, wirausaha, pekerja/karyawan swasta, guru/pendidik, pekerja serabutan
I63: BUKIT BARU | J63: petani/pekebun, guru/pendidik, pekerja/karyawan swasta, pekerja serabutan, buruh industri
I64: PARUNG LAMPE | J64: petani/pekebun, peternak, guru/pendidik, driver/pengemudi, perangkat desa
I65: PUNCAK HARAPAN | J65: petani/pekebun, pembantu/asisten rumah tangga, guru/pendidik, wirausaha, buruh industri
I66: TETEBAWO | J66: petani/pekebun, wirausaha, pekerja serabutan, security/satpam/penjaga keamanan, guru/pendidik
I67: MAKKUASENG | J67: petani/pekebun, wirausaha, tenaga administrasi (tata usaha), pekerja serabutan, buruh industri
