Workbook

Sheet Formulir tanpa judul
A1: Timestamp | B1: Pernyataan Persetujuan Dengan ini saya menyatakan bahwa: Saya telah membaca dan memahami penjelasan mengenai tujuan dan prosedur penelitian. Saya menyadari bahwa partisipasi saya bersifat sukarela dan saya berhak untuk mengundurkan diri kapan saja tanpa k | C1: Nama | D1: Jenis Kelamin | E1: Desa | F1: Nomor HP | G1: Umur | H1: Status di keluarga | I1: Pendidikan terakhir | J1: Status kependudukan | K1: Profesi pekerjaan utama | L1: Pendapatan per bulan | M1: Pengeluaran pulsa per bulan | N1: Apakah anda memiliki HP? | O1: Berapa jumlah HP yang anda miliki? | P1: Berapa kali menggunakan HP dalam sehari? | Q1: Berapa menit rata-rata menggunakan HP per hari? | R1: Untuk apa saja HP digunakan? | S1: Apakah anda memiliki Smartphone? | T1: Berapa jumlah Smartphone yang anda miliki? | U1: Berapa kali menggunakan Smartphone dalam sehari? | V1: Berapa menit rata-rata menggunakan Smartphone per hari? | W1: Untuk apa saja Smartphone digunakan? | X1: Apakah anda memiliki Tablet? | Y1: Berapa jumlah Tablet yang anda miliki? | Z1: Berapa kali menggunakan Tablet dalam sehari? | AA1: Berapa menit rata-rata menggunakan Tablet per hari? | AB1: Untuk apa saja Tablet digunakan? | AC1: Apakah anda memiliki Komputer? | AD1: Berapa jumlah Komputer yang anda miliki? | AE1: Berapa kali menggunakan Komputer dalam sehari? | AF1: Berapa menit rata-rata menggunakan Komputer per hari? | AG1: Untuk apa saja Komputer digunakan? | AH1: Apakah anda memiliki Laptop | AI1: Berapa jumlah Laptop yang anda miliki? | AJ1: Berapa kali menggunakan Laptop dalam sehari? | AK1: Berapa menit rata-rata menggunakan Laptop per hari? | AL1: Untuk apa saja Laptop digunakan? | AM1: Apakah anda memiliki Facebook? | AN1: Berapa kali menggunakan Facebook dalam sehari? | AO1: Berapa menit rata-rata menggunakan Facebook per hari? | AP1: Untuk apa saja Facebook digunakan? | AQ1: Apakah anda memiliki Twitter (X)? | AR1: Berapa kali menggunakan Twitter (X) dalam sehari? | AS1: Berapa menit rata-rata menggunakan Twitter (X) per hari? | AT1: Untuk apa saja Twitter (X) digunakan? | AU1: Apakah anda memiliki Instagram? | AV1: Berapa kali menggunakan Instagram dalam sehari? | AW1: Berapa menit rata-rata menggunakan Instagram per hari? | AX1: Untuk apa saja Instagram digunakan? | AY1: Apakah anda memiliki Whatsapp | AZ1: Berapa kali menggunakan Whatsapp dalam sehari? | BA1: Berapa menit rata-rata menggunakan Whatsapp per hari? | BB1: Untuk apa saja Whatsapp digunakan? | BC1: Apakah anda memiliki Tiktok? | BD1: Berapa kali menggunakan Tiktok dalam sehari? | BE1: Berapa menit rata-rata menggunakan Tiktok per hari? | BF1: Untuk apa saja Tiktok digunakan? | BG1: Apakah anda memiliki Youtube? | BH1: Berapa kali menggunakan Youtube dalam sehari? | BI1: Berapa menit rata-rata menggunakan Youtube per hari? | BJ1: Untuk apa saja Youtube digunakan? | BK1: Apakah anda memiliki Blog? | BL1: Berapa kali menggunakan Blog dalam sehari? | BM1: Berapa menit rata-rata menggunakan Blog per hari? | BN1: Untuk apa saja Blog digunakan? | BO1: Apakah anda menggunakan Shopee? | BP1: Berapa kali menggunakan Shopee dalam sehari? | BQ1: Berapa menit rata-rata menggunakan Shopee per hari? | BR1: Untuk apa saja Shopee digunakan? | BS1: Apakah anda menggunakan Tokopedia? | BT1: Berapa kali menggunakan Tokopedia dalam sehari? | BU1: Berapa menit rata-rata menggunakan Tokopedia per hari? | BV1: Untuk apa saja Tokopedia digunakan? | BW1: Apakah anda menggunakan Bukalapak? | BX1: Berapa kali menggunakan Bukalapak dalam sehari? | BY1: Berapa menit rata-rata menggunakan Bukalapak per hari? | BZ1: Untuk apa saja Bukalapak digunakan? | CA1: Apakah anda menggunakan Lazada? | CB1: Berapa kali menggunakan Lazada dalam sehari? | CC1: Berapa menit rata-rata menggunakan Lazada per hari? | CD1: Untuk apa saja Lazada digunakan? | CE1: Saya mencari informasi yang saya inginkan dari website/blog tertentu | CF1: Saya memilih untuk PERCAYA pada informasi yang saya dapatkan dari website/blog tertentu | CG1: Sebutkan website/blog yang sering anda kunjungi untuk mencari informasi | CH1: Saya mencari informasi yang saya inginkan dari Facebook/Twitter (X)/Instagram/Tiktok | CI1: Saya memilih untuk PERCAYA pada informasi yang saya dapatkan dari Facebook/Twitter (X)/Instagram/Tiktok | CJ1: Saya merasa bahwa informasi yang dimuat di Facebook/Twitter (X)/Instagram/Tiktok itu cocok untuk saya | CK1: Sebutkan Facebook/Twitter (X)/Instagram/Tiktok yang sering anda kunjungi untuk mencari informasi | CL1: Saya mencari informasi yang saya inginkan dari Grup Whatsapp/sejenisnya tertentu | CM1: Saya memilih untuk PERCAYA pada informasi yang saya dapatkan dari Grup Whatsapp/sejenisnya tertentu | CN1: Saya merasa bahwa informasi yang dimuat di Group Chat pilihan saya itu cocok untuk saya | CO1: Sebutkan Grup Whatsapp/sejenisnya yang sering anda gunakan untuk mencari informasi | CP1: Saya mencari informasi yang saya inginkan dari channel Youtube tertentu | CQ1: Saya memilih untuk PERCAYA pada informasi yang saya dapatkan dari channel Youtube tertentu | CR1: Saya merasa bahwa informasi yang dimuat di channel Youtube pilihan saya itu cocok untuk saya | CS1: Sebutkan Youtube yang sering anda kunjungi untuk mencari informasi | CT1: Saya menyukai penyampaian informasi dari website/blog tertentu | CU1: Saya merasa bahwa informasi yang saya dapatkan dari website/blog tertentu perlu untuk saya ketahui | CV1: Saya merasa bahwa informasi yang saya dapatkan dari website/blog tertentu memuaskan keingintahuan saya | CW1: Saya merasa bahwa informasi yang dimuat di website/blog tertentu hanya bersifat hiburan dan tidak berisi informasi penting | CX1: Saya memahami akar permasalahan dari sebuah kasus yang dimuat di website/blog tertentu | CY1: Saya memahami solusi yang ditawarkan atas permasalahan yang dimuat di website/blog tertentu | CZ1: Saya memikirkan setiap informasi yang saya dapatkan dari website/blog tertentu, dan saya tahu mana informasi yang benar/salah | DA1: Saya menyukai penyampaian informasi dari Facebook/Twitter (X)/Instagram/Tiktok tertentu | DB1: Saya merasa bahwa informasi yang saya dapatkan dari Facebook/Twitter (X)/Instagram/Tiktok tertentu perlu untuk saya ketahui | DC1: Saya merasa bahwa informasi yang saya dapatkan dari Facebook/Twitter (X)/Instagram/Tiktok tertentu memuaskan keingintahuan saya | DD1: Saya merasa bahwa informasi yang dimuat di Facebook/Twitter (X)/Instagram/Tiktok tertentu hanya bersifat hiburan dan tidak berisi informasi penting | DE1: Saya memahami akar permasalahan dari sebuah kasus yang dimuat di Facebook/Twitter (X)/Instagram/Tiktok tertentu | DF1: Saya memahami solusi yang ditawarkan atas permasalahan yang dimuat di Facebook/Twitter (X)/Instagram/Tiktok tertentu | DG1: Saya memikirkan setiap informasi yang saya dapatkan dari Facebook/Twitter (X)/Instagram/Tiktok tertentu, dan saya tahu mana informasi yang benar/salah | DH1: Saya menyukai penyampaian informasi dari Grup Whatsapp/sejenisnya tertentu | DI1: Saya merasa bahwa informasi yang saya dapatkan dari Grup Whatsapp/sejenisnya tertentu perlu untuk saya ketahui | DJ1: Saya merasa bahwa informasi yang saya dapatkan dari Grup Whatsapp/sejenisnya tertentu memuaskan keingintahuan saya | DK1: Saya merasa bahwa informasi yang dimuat di Grup Whatsapp/sejenisnya tertentu hanya bersifat hiburan dan tidak berisi informasi penting | DL1: Saya memahami akar permasalahan dari sebuah kasus yang dimuat di Grup Whatsapp/sejenisnya tertentu | DM1: Saya memahami solusi yang ditawarkan atas permasalahan yang dimuat di Grup Whatsapp/sejenisnya tertentu | DN1: Saya memikirkan setiap informasi yang saya dapatkan dari Grup Whatsapp/sejenisnya tertentu, dan saya tahu mana informasi yang benar/salah | DO1: Saya menyukai penyampaian informasi dari channel Youtube tertentu | DP1: Saya merasa bahwa informasi yang saya dapatkan dari channel Youtube tertentu perlu untuk saya ketahui | DQ1: Saya merasa bahwa informasi yang saya dapatkan dari channel Youtube tertentu memuaskan keingintahuan saya | DR1: Saya merasa bahwa informasi yang saya dapatkan dari channel Youtube tertentu memuaskan keingintahuan saya2 | DS1: Saya memahami akar permasalahan dari sebuah kasus yang dimuat di channel Youtube tertentu | DT1: Saya memahami solusi yang ditawarkan atas permasalahan yang dimuat di channel Youtube tertentu | DU1: Saya memikirkan setiap informasi yang saya dapatkan dari channel Youtube, dan saya tahu mana informasi yang benar/salah | DV1: Saya mencoba mencari tahu alasan dan kebenaran dari setiap informasi yang saya dapat dari website/blog tertentu | DW1: Saya membandingkan dan mencocokkan informasi yang saya dapat dari website/blog tertentu dengan website /blog lain | DX1: Saya merasa puas dengan informasi yang saya dapatkan dari website/blog tertentu | DY1: Sebutkan website/blog yang sering anda gunakan untuk mengecek kebenaran Informasi | DZ1: Saya mencoba mencari tahu alasan dan kebenaran dari setiap informasi yang saya dapat dari Facebook/Twitter (X)/Instagram/Tiktok tertentu | EA1: Saya membandingkan dan mencocokkan informasi yang saya dapat dari Facebook/Twitter (X)/Instagram/Tiktok tertentu dengan sumber lain | EB1: Saya merasa puas dengan informasi yang saya dapatkan dari Facebook/Twitter (X)/Instagram/Tiktok tertentu | EC1: Sebutkan Facebook/Twitter (X)/Instagram/Tiktok yang sering anda gunakan untuk mengecek kebenaran Informasi | ED1: Saya mencoba mencari tahu alasan dan kebenaran dari setiap informasi yang saya dapat dari Grup Whatsapp/sejenisnya tertentu | EE1: Saya membandingkan dan mencocokkan informasi yang saya dapat dari Grup Whatsapp/sejenisnya tertentu dengan Grup Whatsapp/sejenisnya yang lain | EF1: Saya merasa puas dengan informasi yang saya dapatkan dari Grup Whatsapp/sejenisnya tertentu | EG1: Sebutkan Grup Whatsapp/sejenisnya yang sering anda gunakan untuk mengecek kebenaran Informasi | EH1: Saya mencoba mencari tahu alasan dan kebenaran dari setiap informasi yang saya dapat dari channel Youtube tertentu | EI1: Saya membandingkan dan mencocokkan informasi yang saya dapat dari channel Youtube tertentu dengan channel Youtube | EJ1: Saya merasa puas dengan informasi yang saya dapatkan dari website/blog tertentu3 | EK1: Sebutkan channel Youtube yang sering anda gunakan untuk mengecek kebenaran Informasi | EL1: Saya membagikan informasi yang saya dapatkan dari website/blog lain di website/blog saya. | EM1: Saya membagikan informasi yang saya dapatkan dari Facebook/Twitter (X)/Instagram/Tiktok di website/blog saya. | EN1: Saya membagikan informasi yang saya dapatkan dari Grup Whatsapp/sejenisnya di website/blog saya. | EO1: Saya membagikan informasi yang saya dapatkan dari channel Youtube di website/blog saya. | EP1: Saya membagikan informasi yang saya dapatkan dari website/blog di akun Facebook/Twitter (X)/Instagram/Tiktok saya. | EQ1: Saya membagikan informasi yang saya dapatkan dari Facebook/Twitter (X)/Instagram/Tiktok lain di Facebook/Twitter (X)/Instagram/Tiktok saya. | ER1: Saya membagikan informasi yang saya dapatkan dari Grup Whatsapp/sejenisnya di Facebook/Twitter (X)/Instagram/Tiktok saya | ES1: Saya membagikan informasi yang saya dapatkan dari channel Youtube di Facebook/Twitter (X)/Instagram/Tiktok saya. | ET1: Saya membagikan informasi yang saya dapatkan dari website/blog di Grup Whatsapp/sejenisnya saya. | EU1: Saya membagikan informasi yang saya dapatkan dari Facebook/Twitter (X)/Instagram/Tiktok di Grup Whatsapp/sejenisnya. | EV1: Saya membagikan informasi yang saya dapatkan dari salah satu Grup Whatsapp ke Grup Whatsapp lain. | EW1: Saya membagikan informasi yang saya dapatkan dari channel Youtube ke Grup Whatsapp saya. | EX1: Saya membagikan informasi yang saya dapatkan dari website/blog lain di channel Youtube saya. | EY1: Saya membagikan informasi yang saya dapatkan dari Facebook/Twitter (X)/Instagram/Tiktok di channel Youtube saya. | EZ1: Saya membagikan informasi yang saya dapatkan dari Grup Whatsapp di channel Youtube saya. | FA1: Saya membagikan informasi yang saya dapatkan dari channel Youtube lain di channel Youtube saya. | FB1: Saya membuat tulisan berisi informasi penting untuk diunggah/upload di website/blog saya | FC1: Saya membuat gambar/video berisi informasi penting untuk diunggah/upload di website/blog saya | FD1: Saya membuat tulisan berisi informasi penting untuk diunggah/upload di akun Facebook/Twitter (X)/Instagram/Tiktok saya | FE1: Saya membuat gambar/video berisi informasi penting untuk diunggah/upload di Facebook/Twitter (X)/Instagram/Tiktok saya | FF1: Saya membuat tulisan berisi informasi penting untuk diunggah/upload di Grup Whatsapp saya | FG1: Saya membuat gambar/video berisi informasi penting untuk diunggah/upload di Grup Whatsapp saya | FH1: Saya membuat gambar/video berisi informasi penting untuk diunggah/upload di channel Youtube saya | FI1: Saya mengetahui sanksi penyebaran berita palsu/HOAX secara hukum | FJ1: Saya dapat mempertanggungjawabkan setiap informasi yang saya sebarkan | FK1: Saya merasa aplikasi PRA Digital mudah untuk digunakan. | FL1: Saya tidak kesulitan memahami fungsi-fungsi dalam aplikasi PRA Digital. | FM1: Saya termasuk orang yang tidak tertarik pada teknologi baru. | FN1: Saya sulit mempelajari penggunaan aplikasi ini dengan cepat. | FO1: Saya tidak percaya teknologi digital dapat meningkatkan kualitas perencanaan pembangunan desa. | FP1: Saya yakin bahwa teknologi seperti aplikasi PRA Digital dapat mendorong kolaborasi yang asyik antarpemuda. | FQ1: Saya merasa penggunaan aplikasi PRA Digital membuat musyawarah menjadi lebih menarik dan menyenangkan. | FR1: Aplikasi ini dapat diprediksi membantu pengambilan keputusan berbasis data. | FS1: Penggunaan aplikasi PRA Digital tidak mempercepat proses diskusi dalam musyawarah. | FT1: Saya tidak senang mencoba teknologi baru untuk mendukung pembangunan desa. | FU1: Aplikasi PRA Digital mendukung saya menyampaikan aspirasi dengan lebih jelas | FV1: Saya menilai bahwa aplikasi PRA Digital ini secara keseluruhan bukan merupakan aplikasi yang baik dan tidak layak digunakan dalam perencanaan pembangunan desa. | FW1: Aplikasi PRA Digital terasa sederhana dalam pengoperasiannya. | FX1: Menggunakan aplikasi PRA Digital ini merupakan pengalaman yang menyenangkan dan saya menyukainya. | FY1: Saya merasa perlu untuk menjadi pelopor terdepan dalam memanfaatkan teknologi di desa saya. | FZ1: Saya merasa nyaman saat menggunakan aplikasi PRA Digital. | GA1: Saya tidak merasa aman ketika menggunakan aplikasi PRA Digital untuk menyampaikan pendapat dan mengikuti diskusi perencanaan desa. | GB1: Saya tidak merasa termotivasi menggunakan teknologi dalam proses musyawarah desa. | GC1: Informasi yang tersedia di aplikasi ini tidak memenuhi ekspektasi dan tidak relevan dengan kebutuhan desa. | GD1: Saya merasa lebih mudah didengar melalui penggunaan aplikasi PRA Digital. | GE1: Petunjuk penggunaan aplikasi PRA Digital tidak jelas dan sulit dimengerti. | GF1: Aplikasi PRA Digital praktis digunakan untuk meningkatkan efektivitas partisipasi saya dalam forum desa. | GG1: Data yang dikumpulkan melalui aplikasi ini berantakan dan tidak berguna untuk perencanaan pembangunan desa. | GH1: Tampilan aplikasi PRA Digital tidak atraktif dan sulit dipahami. | GI1: Aplikasi PRA Digital sulit digunakan oleh orang tanpa latar belakang teknologi. | GJ1: Saya percaya bahwa teknologi inovatif seperti PRA Digital dapat mendorong perubahan positif. | GK1: Saya merasa terdorong untuk mengikuti forum musyawarah setelah menggunakan aplikasi PRA digital. | GL1: Saya merasa kehadiran saya dalam diskusi lebih bermakna setelah adanya platform digital. | GM1: Saya lebih bersemangat untuk terlibat dalam diskusi setelah menggunakan aplikasi PRA digital. | GN1: Aplikasi digital membuat saya merasa memiliki peran dalam proses perencanaan desa. | GO1: Saya merasa memiliki kesempatan yang sama dengan peserta lain untuk berbicara dalam forum diskusi. | GP1: Aplikasi PRA digital memberikan ruang yang setara bagi semua pemuda untuk menyampaikan pendapat. | GQ1: Tidak ada kelompok yang mendominasi diskusi dalam forum digital. | GR1: Saya merasa suara saya dianggap penting dalam forum digital yang difasilitasi oleh aplikasi PRA. | GS1: Saya merasa bebas menyampaikan pendapat dalam forum digital PRA. | GT1: Saya merasa nyaman untuk mengungkapkan gagasan saya di aplikasi PRA. | GU1: Saya dapat menyampaikan kritik atau masukan secara terbuka melalui aplikasi. | GV1: Forum diskusi digital mendorong saya untuk berpendapat lebih aktif dibanding sebelumnya. | GW1: Saya diberi kesempatan untuk terlibat dalam penyusunan rencana pembangunan desa. | GX1: Aplikasi PRA digital memudahkan saya bekerja sama dengan peserta lain dalam merumuskan tindak lanjut. | GY1: Saya merasa kontribusi saya digunakan dalam menyusun hasil akhir diskusi. | GZ1: Saya merasa lebih terlibat dalam proses pengambilan keputusan setelah forum digital dibanding sebelumnya.
A2: 2025/10/05 8:16:41 PM GMT+7 | B2: Saya bersedia menjadi responden dalam penelitian ini | C2: Dina agustin | D2: Perempuan | E2: Desa tanjung dalam | F2: 083830815775 | G2: 17 | H2: Anak | I2: SMP | J2: Penduduk asli | K2: Tidak ada | L2: 0 | M2: 100 | N2: Ya | O2: 1 | P2: 3 | Q2: 30 | R2: Kontak kerabat;Mencari informasi;Menjual produk | S2: Tidak | X2: Tidak | AC2: Tidak | AH2: Tidak | AM2: Ya | AN2: 2 | AO2: 30 | AP2: Kontak kerabat;Mencari informasi;Menjual produk | AQ2: Tidak | AU2: Tidak | AY2: Ya | AZ2: 5 | BA2: 20 | BB2: Kontak kerabat;Mencari informasi;Menjual produk | BC2: Tidak | BG2: Tidak | BK2: Tidak | BO2: Ya | BP2: 2 | BQ2: 10 | BR2: Membeli produk | BS2: Tidak | BW2: Tidak | CA2: Tidak | CE2: 7 | CF2: 7 | CG2: Goggle | CH2: 7 | CI2: 7 | CJ2: 7 | CK2: Facebook | CL2: 7 | CM2: 7 | CN2: 7 | CO2: Karang taruna | CP2: 7 | CQ2: 7 | CR2: 7 | CS2: Channel @indosiar | CT2: 1 | CU2: 1 | CV2: 1 | CW2: 1 | CX2: 1 | CY2: 1 | CZ2: 1 | DA2: 7 | DB2: 7 | DC2: 7 | DD2: 7 | DE2: 7 | DF2: 7 | DG2: 7 | DH2: 7 | DI2: 7 | DJ2: 7 | DK2: 7 | DL2: 7 | DM2: 7 | DN2: 7 | DO2: 5 | DP2: 3 | DQ2: 3 | DR2: 3 | DS2: 3 | DT2: 3 | DU2: 3 | DV2: 1 | DW2: 1 | DX2: 1 | DY2: Tidak ada | DZ2: 7 | EA2: 7 | EB2: 7 | EC2: Facebook | ED2: 7 | EE2: 7 | EF2: 7 | EG2: Group karang taruna | EH2: 1 | EI2: 1 | EJ2: 1 | EK2: @indosiar | EL2: 1 | EM2: 1 | EN2: 1 | EO2: 1 | EP2: 1 | EQ2: 1 | ER2: 1 | ES2: 1 | ET2: 1 | EU2: 2 | EV2: 1 | EW2: 1 | EX2: 1 | EY2: 1 | EZ2: 1 | FA2: 1 | FB2: 2 | FC2: 1 | FD2: 7 | FE2: 7 | FF2: 7 | FG2: 7 | FH2: 7 | FI2: 7 | FJ2: 7 | FK2: 1 | FL2: 3 | FM2: 7 | FN2: 7 | FO2: 7 | FP2: 7 | FQ2: 7 | FR2: 7 | FS2: 7 | FT2: 7 | FU2: 1 | FV2: 7 | FW2: 7 | FX2: 7 | FY2: 7 | FZ2: 7 | GA2: 7 | GB2: 7 | GC2: 7 | GD2: 7 | GE2: 7 | GF2: 7 | GG2: 7 | GH2: 7 | GI2: 7 | GJ2: 7 | GK2: 7 | GL2: 7 | GM2: 7 | GN2: 7 | GO2: 7 | GP2: 7 | GQ2: 7 | GR2: 7 | GS2: 1 | GT2: 1 | GU2: 1 | GV2: 7 | GW2: 7 | GX2: 7 | GY2: 7 | GZ2: 7
A3: 2025/10/05 8:18:32 PM GMT+7 | B3: Saya bersedia menjadi responden dalam penelitian ini | C3: Justita sari | D3: Perempuan | E3: Tanjung dalam Dusun 1 | F3: 082281871996 | G3: 24 | H3: Anak | I3: SMA/SMK | J3: Penduduk asli | K3: Tidak ada | L3: 0 | M3: 100 | N3: Ya | O3: 1 | P3: 3 | Q3: 30 | R3: Kontak kerabat;Hiburan;Mencari informasi | S3: Tidak | X3: Tidak | AC3: Tidak | AH3: Tidak | AM3: Ya | AN3: 2 | AO3: 30 | AP3: Kontak kerabat;Mencari informasi | AQ3: Tidak | AU3: Ya | AV3: 2 | AW3: 20 | AX3: Mencari informasi | AY3: Ya | AZ3: 5 | BA3: 30 | BB3: Kontak kerabat;Mencari informasi | BC3: Ya | BD3: 1 | BE3: 20 | BF3: Hiburan;Mencari informasi | BG3: Ya | BH3: 1 | BI3: 90 | BJ3: Hiburan;Mencari informasi | BK3: Tidak | BO3: Ya | BP3: 2 | BQ3: 30 | BR3: Membeli produk | BS3: Tidak | BW3: Tidak | CA3: Tidak | CE3: 7 | CF3: 7 | CG3: Youtube | CH3: 7 | CI3: 7 | CJ3: 7 | CK3: Facebook | CL3: 7 | CM3: 7 | CN3: 7 | CO3: Karang taruna | CP3: 7 | CQ3: 7 | CR3: 7 | CS3: Indosiar | CT3: 7 | CU3: 7 | CV3: 7 | CW3: 1 | CX3: 7 | CY3: 7 | CZ3: 7 | DA3: 7 | DB3: 7 | DC3: 7 | DD3: 1 | DE3: 7 | DF3: 7 | DG3: 7 | DH3: 7 | DI3: 7 | DJ3: 7 | DK3: 7 | DL3: 7 | DM3: 7 | DN3: 7 | DO3: 7 | DP3: 7 | DQ3: 7 | DR3: 7 | DS3: 7 | DT3: 7 | DU3: 7 | DV3: 7 | DW3: 7 | DX3: 7 | DY3: Youtube | DZ3: 7 | EA3: 7 | EB3: 7 | EC3: Facebook | ED3: 7 | EE3: 7 | EF3: 7 | EG3: Grup Karang taruna | EH3: 7 | EI3: 7 | EJ3: 7 | EK3: Indosiar | EL3: 7 | EM3: 7 | EN3: 7 | EO3: 7 | EP3: 7 | EQ3: 7 | ER3: 7 | ES3: 7 | ET3: 7 | EU3: 7 | EV3: 7 | EW3: 7 | EX3: 7 | EY3: 7 | EZ3: 7 | FA3: 7 | FB3: 7 | FC3: 7 | FD3: 7 | FE3: 7 | FF3: 7 | FG3: 7 | FH3: 7 | FI3: 7 | FJ3: 7 | FK3: 7 | FL3: 7 | FM3: 7 | FN3: 7 | FO3: 7 | FP3: 7 | FQ3: 7 | FR3: 7 | FS3: 7 | FT3: 7 | FU3: 1 | FV3: 7 | FW3: 7 | FX3: 7 | FY3: 7 | FZ3: 7 | GA3: 7 | GB3: 7 | GC3: 7 | GD3: 7 | GE3: 7 | GF3: 7 | GG3: 7 | GH3: 7 | GI3: 7 | GJ3: 7 | GK3: 7 | GL3: 7 | GM3: 7 | GN3: 7 | GO3: 7 | GP3: 7 | GQ3: 7 | GR3: 7 | GS3: 7 | GT3: 7 | GU3: 7 | GV3: 7 | GW3: 7 | GX3: 7 | GY3: 7 | GZ3: 7
A4: 2025/10/05 8:28:14 PM GMT+7 | B4: Saya bersedia menjadi responden dalam penelitian ini | C4: Ria Amelia | D4: Perempuan | E4: Desa Tanjung dalam | F4: 083176446064 | G4: 19 | H4: Anak | I4: Tidak tamat SD | J4: Pendatang | K4: Staf kantor | L4: 500 | M4: 60 | N4: Ya | O4: 1 | P4: 2 | Q4: 1 jam | R4: Lainnya | S4: Ya | T4: 1 | U4: 2 | V4: 60 meniy | W4: Lainnya | X4: Tidak | AC4: Tidak | AH4: Tidak | AM4: Ya | AN4: 5 | AO4: 1 jam | AP4: Mencari informasi | AQ4: Tidak | AU4: Tidak | AY4: Ya | AZ4: 4 | BA4: 1 jam | BB4: Mencari informasi | BC4: Ya | BD4: 1 | BE4: 30 meniy | BF4: Hiburan | BG4: Ya | BH4: 1 | BI4: 20 menit | BJ4: Hiburan | BK4: Tidak | BO4: Ya | BP4: 0 | BQ4: 5 menit | BR4: Membeli produk | BS4: Tidak | BW4: Tidak | CA4: Tidak | CE4: 1 | CF4: 1 | CG4: Tik tok | CH4: 3 | CI4: 3 | CJ4: 3 | CK4: Tik tok | CL4: 5 | CM4: 3 | CN4: 3 | CO4: Facebook | CP4: 6 | CQ4: 6 | CR4: 5 | CS4: Tutorial | CT4: 4 | CU4: 5 | CV4: 5 | CW4: 4 | CX4: 4 | CY4: 3 | CZ4: 6 | DA4: 7 | DB4: 6 | DC4: 5 | DD4: 4 | DE4: 4 | DF4: 4 | DG4: 4 | DH4: 5 | DI4: 4 | DJ4: 4 | DK4: 4 | DL4: 4 | DM4: 4 | DN4: 4 | DO4: 7 | DP4: 7 | DQ4: 7 | DR4: 7 | DS4: 7 | DT4: 7 | DU4: 7 | DV4: 5 | DW4: 5 | DX4: 5 | DY4: Google | DZ4: 7 | EA4: 5 | EB4: 5 | EC4: Facebook | ED4: 7 | EE4: 7 | EF4: 7 | EG4: Karang taruna | EH4: 7 | EI4: 7 | EJ4: 7 | EK4: Mukbang | EL4: 5 | EM4: 5 | EN4: 5 | EO4: 5 | EP4: 5 | EQ4: 5 | ER4: 5 | ES4: 5 | ET4: 5 | EU4: 5 | EV4: 5 | EW4: 5 | EX4: 5 | EY4: 5 | EZ4: 5 | FA4: 5 | FB4: 5 | FC4: 5 | FD4: 5 | FE4: 5 | FF4: 5 | FG4: 5 | FH4: 5 | FI4: 5 | FJ4: 5 | FK4: 3 | FL4: 4 | FM4: 4 | FN4: 3 | FO4: 2 | FP4: 5 | FQ4: 5 | FR4: 4 | FS4: 3 | FT4: 4 | FU4: 5 | FV4: 3 | FW4: 4 | FX4: 4 | FY4: 4 | FZ4: 4 | GA4: 4 | GB4: 4 | GC4: 4 | GD4: 4 | GE4: 4 | GF4: 2 | GG4: 3 | GH4: 3 | GI4: 4 | GJ4: 2 | GK4: 4 | GL4: 5 | GM4: 6 | GN4: 4 | GO4: 7 | GP4: 7 | GQ4: 7 | GR4: 7 | GS4: 3 | GT4: 4 | GU4: 4 | GV4: 4 | GW4: 5 | GX4: 6 | GY4: 6 | GZ4: 4
A5: 2025/10/05 9:42:08 PM GMT+7 | B5: Saya bersedia menjadi responden dalam penelitian ini | C5: Tiara | D5: Perempuan | E5: DUSUN 1 DESA | F5: 083845858159 | G5: 18 | H5: Anak | I5: SMA/SMK | J5: Penduduk asli | K5: Tidak ada | L5: 250 | M5: 200 | N5: Tidak | S5: Ya | T5: 1 | U5: 3 | V5: 20 | W5: Kontak kerabat;Hiburan;Mencari informasi | X5: Tidak | AC5: Tidak | AH5: Tidak | AM5: Ya | AN5: 2 | AO5: 10 | AP5: Kontak kerabat;Hiburan;Mencari informasi | AQ5: Tidak | AU5: Tidak | AY5: Ya | AZ5: 3 | BA5: 15 | BB5: Kontak kerabat;Hiburan;Mencari informasi | BC5: Ya | BD5: 2 | BE5: 15 | BF5: Kontak kerabat;Hiburan;Mencari informasi | BG5: Tidak | BK5: Tidak | BO5: Tidak | BS5: Tidak | BW5: Tidak | CA5: Tidak | CE5: 4 | CF5: 4 | CG5: Fecebok | CH5: 7 | CI5: 7 | CJ5: 7 | CK5: Fecebok | CL5: 7 | CM5: 7 | CN5: 7 | CO5: Grup desa | CP5: 5 | CQ5: 4 | CR5: 4 | CS5: Youtube | CT5: 7 | CU5: 7 | CV5: 7 | CW5: 7 | CX5: 7 | CY5: 7 | CZ5: 7 | DA5: 7 | DB5: 7 | DC5: 7 | DD5: 7 | DE5: 7 | DF5: 7 | DG5: 7 | DH5: 7 | DI5: 7 | DJ5: 7 | DK5: 7 | DL5: 7 | DM5: 7 | DN5: 7 | DO5: 7 | DP5: 7 | DQ5: 7 | DR5: 7 | DS5: 7 | DT5: 7 | DU5: 7 | DV5: 7 | DW5: 7 | DX5: 7 | DY5: Berita | DZ5: 6 | EA5: 7 | EB5: 7 | EC5: Berita | ED5: 4 | EE5: 1 | EF5: 1 | EG5: Fb | EH5: 5 | EI5: 5 | EJ5: 7 | EK5: Berita pali | EL5: 7 | EM5: 7 | EN5: 7 | EO5: 7 | EP5: 7 | EQ5: 7 | ER5: 7 | ES5: 7 | ET5: 7 | EU5: 7 | EV5: 7 | EW5: 7 | EX5: 7 | EY5: 7 | EZ5: 7 | FA5: 7 | FB5: 7 | FC5: 7 | FD5: 7 | FE5: 7 | FF5: 7 | FG5: 7 | FH5: 7 | FI5: 7 | FJ5: 7 | FK5: 7 | FL5: 7 | FM5: 7 | FN5: 7 | FO5: 7 | FP5: 7 | FQ5: 7 | FR5: 7 | FS5: 7 | FT5: 7 | FU5: 1 | FV5: 7 | FW5: 7 | FX5: 7 | FY5: 7 | FZ5: 7 | GA5: 7 | GB5: 7 | GC5: 7 | GD5: 7 | GE5: 7 | GF5: 7 | GG5: 7 | GH5: 7 | GI5: 7 | GJ5: 7 | GK5: 6 | GL5: 6 | GM5: 6 | GN5: 6 | GO5: 7 | GP5: 7 | GQ5: 7 | GR5: 7 | GS5: 7 | GT5: 7 | GU5: 7 | GV5: 7 | GW5: 7 | GX5: 7 | GY5: 7 | GZ5: 7
A6: 2025/10/05 9:58:53 PM GMT+7 | B6: Saya bersedia menjadi responden dalam penelitian ini | C6: Doni Maryanto | D6: Laki-laki | E6: Dusun II Desa Tanjung Dalam | F6: 045379450163 | G6: 37 | H6: KK | I6: SMA/SMK | J6: Penduduk asli | K6: Petani | L6: 1000.000 | M6: 150.000 | N6: Ya | O6: 1 | P6: 6 | Q6: 20-30 menit | R6: Kontak kerabat;Hiburan;Mencari informasi;Membeli produk;Lainnya | S6: Ya | T6: 1 | U6: 6 | V6: 20-30 | W6: Kontak kerabat;Hiburan;Mencari informasi;Membeli produk;Menjual produk;Lainnya | X6: Tidak | AC6: Tidak | AH6: Tidak | AM6: Ya | AN6: 2 | AO6: 5 | AP6: Kontak kerabat;Hiburan;Mencari informasi;Lainnya | AQ6: Tidak | AU6: Tidak | AY6: Ya | AZ6: 10 | BA6: 20-30 | BB6: Kontak kerabat;Hiburan;Mencari informasi;Lainnya | BC6: Ya | BD6: 10 | BE6: 20-30 | BF6: Kontak kerabat;Hiburan;Mencari informasi;Membeli produk;Menjual produk;Lainnya | BG6: Ya | BH6: 5 | BI6: 5 | BJ6: Mencari informasi;Membeli produk;Lainnya | BK6: Tidak | BO6: Ya | BP6: 2 | BQ6: 5 | BR6: Mencari informasi;Membeli produk;Lainnya | BS6: Tidak | BW6: Tidak | CA6: Tidak | CE6: 7 | CF6: 5 | CG6: SumateraEkspres https://sumateraekspres.bacakoran.co Sumatera Ekspres | CH6: 3 | CI6: 3 | CJ6: 3 | CK6: Tiktok | CL6: 7 | CM6: 1 | CN6: 1 | CO6: . | CP6: 1 | CQ6: 1 | CR6: 1 | CS6: . | CT6: 7 | CU6: 7 | CV6: 6 | CW6: 2 | CX6: 6 | CY6: 4 | CZ6: 5 | DA6: 4 | DB6: 5 | DC6: 7 | DD6: 6 | DE6: 6 | DF6: 5 | DG6: 5 | DH6: 6 | DI6: 6 | DJ6: 6 | DK6: 6 | DL6: 5 | DM6: 6 | DN6: 6 | DO6: 7 | DP6: 7 | DQ6: 7 | DR6: 7 | DS6: 7 | DT6: 7 | DU6: 7 | DV6: 7 | DW6: 7 | DX6: 7 | DY6: YouTube dan Google | DZ6: 7 | EA6: 7 | EB6: 7 | EC6: Facebook tiktok google | ED6: 7 | EE6: 7 | EF6: 7 | EG6: WhatsApp | EH6: 7 | EI6: 7 | EJ6: 7 | EK6: Youtube | EL6: 7 | EM6: 7 | EN6: 7 | EO6: 7 | EP6: 7 | EQ6: 7 | ER6: 7 | ES6: 7 | ET6: 6 | EU6: 7 | EV6: 7 | EW6: 7 | EX6: 7 | EY6: 7 | EZ6: 7 | FA6: 7 | FB6: 7 | FC6: 7 | FD6: 7 | FE6: 7 | FF6: 7 | FG6: 7 | FH6: 7 | FI6: 7 | FJ6: 7 | FK6: 7 | FL6: 7 | FM6: 1 | FN6: 1 | FO6: 1 | FP6: 7 | FQ6: 7 | FR6: 7 | FS6: 1 | FT6: 1 | FU6: 7 | FV6: 1 | FW6: 7 | FX6: 7 | FY6: 7 | FZ6: 7 | GA6: 1 | GB6: 1 | GC6: 1 | GD6: 7 | GE6: 1 | GF6: 7 | GG6: 1 | GH6: 1 | GI6: 1 | GJ6: 7 | GK6: 7 | GL6: 7 | GM6: 7 | GN6: 7 | GO6: 7 | GP6: 7 | GQ6: 7 | GR6: 7 | GS6: 7 | GT6: 7 | GU6: 7 | GV6: 7 | GW6: 7 | GX6: 7 | GY6: 7 | GZ6: 7
A7: 2025/10/05 10:13:35 PM GMT+7 | B7: Saya bersedia menjadi responden dalam penelitian ini | C7: Siti Nurbaiti | D7: Perempuan | E7: Dusun 2 Desa Tanjung Dalam | F7: 081367101195 | G7: 22 | H7: Anak | I7: D1/D2/D3 | J7: Penduduk asli | K7: Bidan | L7: 500.000 | M7: 150.000 | N7: Tidak | S7: Ya | T7: 1 | U7: 10 | V7: 1 jam | W7: Kontak kerabat;Hiburan;Mencari informasi;Membeli produk | X7: Tidak | AC7: Tidak | AH7: Tidak | AM7: Ya | AN7: 2 | AO7: 5 menit | AP7: Kontak kerabat;Hiburan;Mencari informasi | AQ7: Tidak | AU7: Ya | AV7: 1 | AW7: 5 menit | AX7: Hiburan;Mencari informasi;Lainnya | AY7: Ya | AZ7: 10 | BA7: 30 menit | BB7: Kontak kerabat;Hiburan;Mencari informasi | BC7: Ya | BD7: 10 | BE7: 1 jam | BF7: Hiburan;Mencari informasi;Membeli produk | BG7: Tidak | BK7: Tidak | BO7: Ya | BP7: 1 | BQ7: 30 | BR7: Membeli produk | BS7: Tidak | BW7: Tidak | CA7: Tidak | CE7: 7 | CF7: 7 | CG7: Geoogle,tik tok,fecebook | CH7: 7 | CI7: 7 | CJ7: 7 | CK7: Berita Pali/Prabumulih,Prabumulih ngehits | CL7: 7 | CM7: 7 | CN7: 7 | CO7: Info SKP Bidan 5 dan | CP7: 7 | CQ7: 7 | CR7: 7 | CS7: Youtube Kok bisa | CT7: 7 | CU7: 7 | CV7: 7 | CW7: 1 | CX7: 7 | CY7: 7 | CZ7: 7 | DA7: 7 | DB7: 1 | DC7: 7 | DD7: 1 | DE7: 7 | DF7: 7 | DG7: 7 | DH7: 7 | DI7: 7 | DJ7: 7 | DK7: 1 | DL7: 7 | DM7: 7 | DN7: 7 | DO7: 7 | DP7: 7 | DQ7: 7 | DR7: 7 | DS7: 7 | DT7: 7 | DU7: 7 | DV7: 5 | DW7: 6 | DX7: 5 | DY7: Tiktok,geoogle | DZ7: 6 | EA7: 6 | EB7: 7 | EC7: Berita pali,Prabumulihngehits | ED7: 4 | EE7: 5 | EF7: 4 | EG7: Info skp | EH7: 7 | EI7: 5 | EJ7: 5 | EK7: Youtube kok bisa | EL7: 4 | EM7: 4 | EN7: 4 | EO7: 4 | EP7: 4 | EQ7: 3 | ER7: 3 | ES7: 3 | ET7: 2 | EU7: 3 | EV7: 2 | EW7: 3 | EX7: 3 | EY7: 2 | EZ7: 3 | FA7: 2 | FB7: 2 | FC7: 5 | FD7: 2 | FE7: 3 | FF7: 2 | FG7: 2 | FH7: 2 | FI7: 6 | FJ7: 5 | FK7: 6 | FL7: 5 | FM7: 3 | FN7: 5 | FO7: 5 | FP7: 6 | FQ7: 4 | FR7: 5 | FS7: 4 | FT7: 3 | FU7: 5 | FV7: 2 | FW7: 3 | FX7: 4 | FY7: 5 | FZ7: 2 | GA7: 3 | GB7: 3 | GC7: 3 | GD7: 5 | GE7: 2 | GF7: 6 | GG7: 1 | GH7: 2 | GI7: 4 | GJ7: 6 | GK7: 6 | GL7: 5 | GM7: 5 | GN7: 6 | GO7: 6 | GP7: 6 | GQ7: 5 | GR7: 5 | GS7: 6 | GT7: 5 | GU7: 3 | GV7: 6 | GW7: 5 | GX7: 6 | GY7: 5 | GZ7: 5
A8: 2025/10/05 10:33:27 PM GMT+7 | B8: Saya bersedia menjadi responden dalam penelitian ini | C8: LISTA | D8: Perempuan | E8: DUSUN 2 TANJUNG DALAM | F8: 085279685959 | G8: 20 | H8: Anak | I8: SMA/SMK | J8: Penduduk asli | K8: LES MEMBACA DAN IQRO | L8: 200.000 | M8: 100.000 | N8: Ya | O8: 0 | P8: 0 | Q8: 0 | R8: Kontak kerabat | S8: Ya | T8: 2 | U8: 50 | V8: 360 | W8: Kontak kerabat;Hiburan;Mencari informasi | X8: Tidak | AC8: Tidak | AH8: Tidak | AM8: Ya | AN8: 5 | AO8: 120 | AP8: Mencari informasi | AQ8: Tidak | AU8: Tidak | AY8: Ya | AZ8: 50 | BA8: 120 | BB8: Kontak kerabat | BC8: Tidak | BG8: Tidak | BK8: Tidak | BO8: Tidak | BS8: Tidak | BW8: Tidak | CA8: Tidak | CE8: 6 | CF8: 6 | CG8: Google,YouTube | CH8: 6 | CI8: 5 | CJ8: 4 | CK8: Berita Pali | CL8: 3 | CM8: 3 | CN8: 3 | CO8: Sensus | CP8: 6 | CQ8: 6 | CR8: 6 | CS8: Raymond chin dan geraldvincentt | CT8: 4 | CU8: 4 | CV8: 4 | CW8: 5 | CX8: 4 | CY8: 3 | CZ8: 5 | DA8: 4 | DB8: 3 | DC8: 3 | DD8: 5 | DE8: 3 | DF8: 3 | DG8: 4 | DH8: 5 | DI8: 5 | DJ8: 4 | DK8: 5 | DL8: 3 | DM8: 3 | DN8: 4 | DO8: 7 | DP8: 5 | DQ8: 7 | DR8: 7 | DS8: 4 | DT8: 4 | DU8: 6 | DV8: 5 | DW8: 5 | DX8: 5 | DY8: Wikipedia | DZ8: 6 | EA8: 6 | EB8: 5 | EC8: Info Timnas Indonesia | ED8: 6 | EE8: 6 | EF8: 5 | EG8: PEMUDA PEMUDI HIJRAH | EH8: 6 | EI8: 5 | EJ8: 7 | EK8: Raymond chin dan geraldvincentt | EL8: 3 | EM8: 5 | EN8: 6 | EO8: 6 | EP8: 2 | EQ8: 3 | ER8: 3 | ES8: 4 | ET8: 4 | EU8: 5 | EV8: 2 | EW8: 2 | EX8: 1 | EY8: 3 | EZ8: 3 | FA8: 3 | FB8: 2 | FC8: 2 | FD8: 2 | FE8: 2 | FF8: 2 | FG8: 2 | FH8: 2 | FI8: 6 | FJ8: 5 | FK8: 3 | FL8: 3 | FM8: 4 | FN8: 5 | FO8: 5 | FP8: 4 | FQ8: 5 | FR8: 6 | FS8: 4 | FT8: 5 | FU8: 3 | FV8: 4 | FW8: 5 | FX8: 4 | FY8: 4 | FZ8: 4 | GA8: 3 | GB8: 4 | GC8: 4 | GD8: 5 | GE8: 4 | GF8: 4 | GG8: 4 | GH8: 5 | GI8: 4 | GJ8: 5 | GK8: 5 | GL8: 6 | GM8: 5 | GN8: 6 | GO8: 6 | GP8: 6 | GQ8: 5 | GR8: 4 | GS8: 4 | GT8: 4 | GU8: 4 | GV8: 4 | GW8: 5 | GX8: 4 | GY8: 4 | GZ8: 4
A9: 2025/10/06 8:17:40 AM GMT+7 | B9: Saya bersedia menjadi responden dalam penelitian ini | C9: Lilis karlina | D9: Perempuan | E9: Tanjung dalam | F9: 082281761214 | G9: 22 | H9: Anak | I9: SMA/SMK | J9: Penduduk asli | K9: Stap kantor kades | L9: 5000.00 | M9: 60 | N9: Ya | O9: 1 | P9: 2 | Q9: 1 jm | R9: Mencari informasi | S9: Tidak | X9: Tidak | AC9: Tidak | AH9: Tidak | AM9: Ya | AN9: 7 | AO9: 2 | AP9: Kontak kerabat;Hiburan;Mencari informasi;Menjual produk | AQ9: Tidak | AU9: Ya | AV9: 2 | AW9: 1 | AX9: Hiburan | AY9: Ya | AZ9: 5 | BA9: 1 jam | BB9: Kontak kerabat;Hiburan;Mencari informasi;Menjual produk | BC9: Tidak | BG9: Ya | BH9: 1 | BI9: 1 | BJ9: Hiburan | BK9: Tidak | BO9: Ya | BP9: 2 | BQ9: 2 | BR9: Membeli produk | BS9: Tidak | BW9: Tidak | CA9: Tidak | CE9: 2 | CF9: 1 | CG9: Vidio | CH9: 7 | CI9: 6 | CJ9: 3 | CK9: Facebook | CL9: 5 | CM9: 3 | CN9: 4 | CO9: Grup perangkat | CP9: 1 | CQ9: 1 | CR9: 2 | CS9: YouTube | CT9: 1 | CU9: 1 | CV9: 1 | CW9: 1 | CX9: 1 | CY9: 1 | CZ9: 1 | DA9: 1 | DB9: 1 | DC9: 1 | DD9: 1 | DE9: 1 | DF9: 1 | DG9: 1 | DH9: 7 | DI9: 7 | DJ9: 7 | DK9: 7 | DL9: 7 | DM9: 7 | DN9: 7 | DO9: 1 | DP9: 1 | DQ9: 7 | DR9: 7 | DS9: 7 | DT9: 6 | DU9: 7 | DV9: 1 | DW9: 1 | DX9: 1 | DY9: WA | DZ9: 1 | EA9: 1 | EB9: 7 | EC9: Facebook | ED9: 1 | EE9: 7 | EF9: 5 | EG9: Grup perangkat | EH9: 1 | EI9: 1 | EJ9: 1 | EK9: Wa | EL9: 1 | EM9: 1 | EN9: 1 | EO9: 1 | EP9: 1 | EQ9: 1 | ER9: 1 | ES9: 5 | ET9: 5 | EU9: 3 | EV9: 2 | EW9: 2 | EX9: 5 | EY9: 7 | EZ9: 1 | FA9: 1 | FB9: 1 | FC9: 2 | FD9: 4 | FE9: 6 | FF9: 1 | FG9: 1 | FH9: 1 | FI9: 3 | FJ9: 2 | FK9: 1 | FL9: 1 | FM9: 1 | FN9: 1 | FO9: 1 | FP9: 1 | FQ9: 1 | FR9: 1 | FS9: 1 | FT9: 1 | FU9: 7 | FV9: 1 | FW9: 1 | FX9: 1 | FY9: 1 | FZ9: 1 | GA9: 1 | GB9: 1 | GC9: 1 | GD9: 1 | GE9: 1 | GF9: 1 | GG9: 1 | GH9: 1 | GI9: 1 | GJ9: 1 | GK9: 1 | GL9: 1 | GM9: 1 | GN9: 1 | GO9: 1 | GP9: 1 | GQ9: 1 | GR9: 1 | GS9: 1 | GT9: 1 | GU9: 1 | GV9: 1 | GW9: 1 | GX9: 1 | GY9: 1 | GZ9: 1
A10: 2025/10/06 4:11:11 PM GMT+7 | B10: Saya bersedia menjadi responden dalam penelitian ini | C10: MEILANI ZEMILLA | D10: Perempuan | E10: Dusun 1 desa lunas jaya | F10: 082282552189 | G10: 24 | H10: Istri | I10: SMA/SMK | J10: Penduduk asli | K10: Sekretaris Desa | L10: 2950000 | M10: 400 | N10: Ya | O10: 1 | P10: 15 | Q10: 3 | R10: Kontak kerabat;Hiburan;Mencari informasi;Membeli produk | S10: Ya | T10: 1 | U10: 12 | V10: 60 | W10: Kontak kerabat;Hiburan;Mencari informasi;Membeli produk | X10: Tidak | AC10: Tidak | AH10: Ya | AI10: 1 | AJ10: 12 | AK10: 60 | AL10: Lainnya | AM10: Ya | AN10: 15 | AO10: 100 | AP10: Kontak kerabat;Hiburan;Mencari informasi;Membeli produk | AQ10: Tidak | AU10: Ya | AV10: 5 | AW10: 80 | AX10: Lainnya | AY10: Ya | AZ10: 15 | BA10: 150 | BB10: Kontak kerabat;Hiburan;Mencari informasi;Membeli produk | BC10: Ya | BD10: 12 | BE10: 100 | BF10: Hiburan;Mencari informasi;Membeli produk | BG10: Ya | BH10: 6 | BI10: 60 | BJ10: Hiburan | BK10: Tidak | BO10: Tidak | BS10: Tidak | BW10: Tidak | CA10: Tidak | CE10: 1 | CF10: 1 | CG10: Tidak ada | CH10: 1 | CI10: 7 | CJ10: 7 | CK10: Live tiktok | CL10: 7 | CM10: 7 | CN10: 7 | CO10: Grup sekdes sekacamatan tanah Abang | CP10: 7 | CQ10: 7 | CR10: 7 | CS10: Hiburan musik | CT10: 1 | CU10: 1 | CV10: 1 | CW10: 1 | CX10: 1 | CY10: 1 | CZ10: 1 | DA10: 7 | DB10: 7 | DC10: 7 | DD10: 7 | DE10: 7 | DF10: 7 | DG10: 7 | DH10: 7 | DI10: 7 | DJ10: 7 | DK10: 7 | DL10: 7 | DM10: 7 | DN10: 7 | DO10: 4 | DP10: 4 | DQ10: 4 | DR10: 5 | DS10: 4 | DT10: 4 | DU10: 4 | DV10: 3 | DW10: 3 | DX10: 3 | DY10: Canva | DZ10: 7 | EA10: 7 | EB10: 7 | EC10: Bansos pkh | ED10: 7 | EE10: 7 | EF10: 7 | EG10: Sekdes sekacamatan tanah Abang, perangkat desa lunas jaya | EH10: 4 | EI10: 4 | EJ10: 4 | EK10: Hiburan berita | EL10: 1 | EM10: 1 | EN10: 1 | EO10: 1 | EP10: 1 | EQ10: 1 | ER10: 1 | ES10: 1 | ET10: 1 | EU10: 1 | EV10: 1 | EW10: 1 | EX10: 1 | EY10: 1 | EZ10: 2 | FA10: 2 | FB10: 2 | FC10: 2 | FD10: 2 | FE10: 7 | FF10: 7 | FG10: 7 | FH10: 7 | FI10: 7 | FJ10: 7 | FK10: 3 | FL10: 3 | FM10: 3 | FN10: 3 | FO10: 3 | FP10: 3 | FQ10: 3 | FR10: 3 | FS10: 3 | FT10: 3 | FU10: 5 | FV10: 3 | FW10: 3 | FX10: 3 | FY10: 3 | FZ10: 3 | GA10: 3 | GB10: 3 | GC10: 3 | GD10: 3 | GE10: 3 | GF10: 4 | GG10: 4 | GH10: 4 | GI10: 3 | GJ10: 3 | GK10: 3 | GL10: 3 | GM10: 3 | GN10: 3 | GO10: 4 | GP10: 4 | GQ10: 3 | GR10: 4 | GS10: 3 | GT10: 3 | GU10: 3 | GV10: 3 | GW10: 5 | GX10: 4 | GY10: 4 | GZ10: 4
A11: 2025/10/06 4:14:26 PM GMT+7 | B11: Saya bersedia menjadi responden dalam penelitian ini | C11: Ayu sonya | D11: Perempuan | E11: Desa lunas jaya | F11: 085273962249 | G11: 25 | H11: Anak | I11: D1/D2/D3 | J11: Pendatang | K11: Bidan | L11: 800000 | M11: 240000 | N11: Ya | O11: 1 | P11: 13 | Q11: 780 | R11: Kontak kerabat;Hiburan;Mencari informasi;Membeli produk | S11: Ya | T11: 1 | U11: 13 | V11: 780 | W11: Kontak kerabat;Hiburan;Mencari informasi;Membeli produk | X11: Tidak | AC11: Tidak | AH11: Ya | AI11: 1 | AJ11: 1 | AK11: 60 | AL11: Lainnya | AM11: Ya | AN11: 3 | AO11: 60 | AP11: Hiburan;Mencari informasi | AQ11: Tidak | AU11: Ya | AV11: 1 | AW11: 60 | AX11: Hiburan;Mencari informasi | AY11: Ya | AZ11: 10 | BA11: 780 | BB11: Kontak kerabat;Hiburan;Mencari informasi;Membeli produk;Menjual produk | BC11: Ya | BD11: 10 | BE11: 780 | BF11: Hiburan;Mencari informasi;Membeli produk | BG11: Ya | BH11: 2 | BI11: 120 | BJ11: Hiburan;Mencari informasi | BK11: Tidak | BO11: Ya | BP11: 2 | BQ11: 120 | BR11: Membeli produk | BS11: Tidak | BW11: Tidak | CA11: Tidak | CE11: 4 | CF11: 2 | CG11: Tidak ada | CH11: 7 | CI11: 7 | CJ11: 7 | CK11: Tentang pppk | CL11: 7 | CM11: 7 | CN11: 5 | CO11: Puskesmas | CP11: 4 | CQ11: 4 | CR11: 4 | CS11: Tutorial | CT11: 3 | CU11: 3 | CV11: 4 | CW11: 3 | CX11: 3 | CY11: 3 | CZ11: 3 | DA11: 6 | DB11: 6 | DC11: 6 | DD11: 6 | DE11: 6 | DF11: 6 | DG11: 6 | DH11: 6 | DI11: 6 | DJ11: 6 | DK11: 6 | DL11: 6 | DM11: 6 | DN11: 6 | DO11: 3 | DP11: 3 | DQ11: 3 | DR11: 3 | DS11: 3 | DT11: 3 | DU11: 3 | DV11: 5 | DW11: 5 | DX11: 5 | DY11: Tidak ada | DZ11: 5 | EA11: 5 | EB11: 5 | EC11: Pali update | ED11: 3 | EE11: 3 | EF11: 3 | EG11: Puskesmas | EH11: 3 | EI11: 3 | EJ11: 3 | EK11: Tidak ada | EL11: 3 | EM11: 3 | EN11: 3 | EO11: 3 | EP11: 3 | EQ11: 3 | ER11: 3 | ES11: 3 | ET11: 3 | EU11: 3 | EV11: 6 | EW11: 4 | EX11: 3 | EY11: 3 | EZ11: 3 | FA11: 3 | FB11: 3 | FC11: 3 | FD11: 3 | FE11: 3 | FF11: 3 | FG11: 3 | FH11: 3 | FI11: 3 | FJ11: 3 | FK11: 3 | FL11: 3 | FM11: 3 | FN11: 3 | FO11: 3 | FP11: 3 | FQ11: 3 | FR11: 3 | FS11: 3 | FT11: 3 | FU11: 5 | FV11: 3 | FW11: 3 | FX11: 3 | FY11: 3 | FZ11: 3 | GA11: 3 | GB11: 3 | GC11: 3 | GD11: 3 | GE11: 3 | GF11: 3 | GG11: 3 | GH11: 3 | GI11: 3 | GJ11: 3 | GK11: 5 | GL11: 5 | GM11: 5 | GN11: 5 | GO11: 6 | GP11: 5 | GQ11: 5 | GR11: 4 | GS11: 3 | GT11: 3 | GU11: 3 | GV11: 3 | GW11: 3 | GX11: 3 | GY11: 3 | GZ11: 3
A12: 2025/10/06 4:15:02 PM GMT+7 | B12: Saya bersedia menjadi responden dalam penelitian ini | C12: Amelia agesti | D12: Perempuan | E12: Lunas jaya | F12: 082278724577 | G12: 27 | H12: Istri | I12: D1/D2/D3 | J12: Penduduk asli | K12: Bidan desa | L12: 800 | M12: 150 | N12: Ya | O12: 1 | P12: 6 | Q12: 3 jam | R12: Lainnya | S12: Ya | T12: 1 | U12: 6 | V12: 3 jam | W12: Lainnya | X12: Tidak | AC12: Tidak | AH12: Tidak | AM12: Ya | AN12: 5 | AO12: 2 | AP12: Lainnya | AQ12: Tidak | AU12: Tidak | AY12: Ya | AZ12: 10 | BA12: 4 | BB12: Lainnya | BC12: Tidak | BG12: Ya | BH12: 2 | BI12: 3 | BJ12: Lainnya | BK12: Tidak | BO12: Tidak | BS12: Tidak | BW12: Tidak | CA12: Tidak | CE12: 1 | CF12: 1 | CG12: Tidak ada | CH12: 7 | CI12: 4 | CJ12: 7 | CK12: Bkpsdm | CL12: 7 | CM12: 7 | CN12: 5 | CO12: Grub whatsapp puskesmas | CP12: 4 | CQ12: 1 | CR12: 1 | CS12: Masalah obat | CT12: 2 | CU12: 3 | CV12: 3 | CW12: 2 | CX12: 4 | CY12: 3 | CZ12: 3 | DA12: 3 | DB12: 2 | DC12: 3 | DD12: 3 | DE12: 3 | DF12: 4 | DG12: 3 | DH12: 3 | DI12: 1 | DJ12: 1 | DK12: 3 | DL12: 3 | DM12: 3 | DN12: 3 | DO12: 1 | DP12: 1 | DQ12: 2 | DR12: 2 | DS12: 2 | DT12: 3 | DU12: 3 | DV12: 3 | DW12: 3 | DX12: 2 | DY12: Tidak ada | DZ12: 2 | EA12: 1 | EB12: 3 | EC12: Tidak ada | ED12: 2 | EE12: 2 | EF12: 2 | EG12: Tidak ada | EH12: 2 | EI12: 2 | EJ12: 3 | EK12: Tidak ada | EL12: 2 | EM12: 2 | EN12: 3 | EO12: 3 | EP12: 3 | EQ12: 2 | ER12: 2 | ES12: 3 | ET12: 5 | EU12: 3 | EV12: 4 | EW12: 4 | EX12: 4 | EY12: 3 | EZ12: 2 | FA12: 3 | FB12: 3 | FC12: 4 | FD12: 3 | FE12: 3 | FF12: 3 | FG12: 3 | FH12: 3 | FI12: 3 | FJ12: 3 | FK12: 3 | FL12: 3 | FM12: 3 | FN12: 3 | FO12: 3 | FP12: 3 | FQ12: 3 | FR12: 3 | FS12: 3 | FT12: 3 | FU12: 5 | FV12: 3 | FW12: 3 | FX12: 3 | FY12: 3 | FZ12: 3 | GA12: 3 | GB12: 3 | GC12: 3 | GD12: 3 | GE12: 3 | GF12: 3 | GG12: 3 | GH12: 2 | GI12: 2 | GJ12: 3 | GK12: 3 | GL12: 3 | GM12: 3 | GN12: 3 | GO12: 3 | GP12: 3 | GQ12: 3 | GR12: 3 | GS12: 3 | GT12: 3 | GU12: 3 | GV12: 3 | GW12: 3 | GX12: 3 | GY12: 3 | GZ12: 3
A13: 2025/10/06 4:15:16 PM GMT+7 | B13: Saya bersedia menjadi responden dalam penelitian ini | C13: Hernita | D13: Perempuan | E13: Dusun 2 desa lunas jaya | F13: 085378389842 | G13: 30 | H13: Anak | I13: SMA/SMK | J13: Penduduk asli | K13: Perangkat desa | L13: 2000.000 | M13: 100.000 | N13: Ya | O13: 1 | P13: 15 | Q13: 1000 | R13: Kontak kerabat;Hiburan;Mencari informasi;Membeli produk;Menjual produk | S13: Ya | T13: 1 | U13: 1 | V13: 1000 | W13: Kontak kerabat;Hiburan;Mencari informasi;Membeli produk;Menjual produk | X13: Tidak | AC13: Tidak | AH13: Tidak | AM13: Ya | AN13: 2 | AO13: 240 | AP13: Kontak kerabat;Hiburan;Mencari informasi;Membeli produk;Menjual produk | AQ13: Tidak | AU13: Ya | AV13: 2 | AW13: 240 | AX13: Kontak kerabat;Hiburan;Mencari informasi | AY13: Ya | AZ13: 5 | BA13: 500 | BB13: Kontak kerabat;Hiburan;Mencari informasi;Membeli produk;Menjual produk | BC13: Ya | BD13: 3 | BE13: 240 | BF13: Kontak kerabat;Hiburan;Mencari informasi;Membeli produk | BG13: Tidak | BK13: Tidak | BO13: Ya | BP13: 1 | BQ13: 30 | BR13: Membeli produk | BS13: Tidak | BW13: Tidak | CA13: Tidak | CE13: 6 | CF13: 6 | CG13: Kemensos | CH13: 7 | CI13: 7 | CJ13: 7 | CK13: Kemendes | CL13: 7 | CM13: 7 | CN13: 6 | CO13: Group keluarga | CP13: 4 | CQ13: 5 | CR13: 5 | CS13: Music/lagu | CT13: 3 | CU13: 5 | CV13: 5 | CW13: 6 | CX13: 6 | CY13: 5 | CZ13: 5 | DA13: 6 | DB13: 6 | DC13: 6 | DD13: 6 | DE13: 5 | DF13: 6 | DG13: 6 | DH13: 7 | DI13: 6 | DJ13: 6 | DK13: 6 | DL13: 5 | DM13: 6 | DN13: 6 | DO13: 6 | DP13: 6 | DQ13: 6 | DR13: 6 | DS13: 5 | DT13: 5 | DU13: 6 | DV13: 6 | DW13: 6 | DX13: 6 | DY13: Google | DZ13: 7 | EA13: 6 | EB13: 6 | EC13: Google | ED13: 6 | EE13: 7 | EF13: 6 | EG13: Perangkat desa | EH13: 7 | EI13: 7 | EJ13: 7 | EK13: Berita terkini | EL13: 5 | EM13: 7 | EN13: 6 | EO13: 6 | EP13: 7 | EQ13: 6 | ER13: 5 | ES13: 6 | ET13: 7 | EU13: 7 | EV13: 6 | EW13: 7 | EX13: 7 | EY13: 6 | EZ13: 7 | FA13: 7 | FB13: 7 | FC13: 7 | FD13: 7 | FE13: 7 | FF13: 7 | FG13: 7 | FH13: 7 | FI13: 7 | FJ13: 7 | FK13: 3 | FL13: 3 | FM13: 3 | FN13: 3 | FO13: 4 | FP13: 3 | FQ13: 3 | FR13: 3 | FS13: 3 | FT13: 3 | FU13: 5 | FV13: 3 | FW13: 3 | FX13: 4 | FY13: 3 | FZ13: 4 | GA13: 3 | GB13: 3 | GC13: 3 | GD13: 3 | GE13: 3 | GF13: 3 | GG13: 3 | GH13: 3 | GI13: 3 | GJ13: 3 | GK13: 3 | GL13: 3 | GM13: 3 | GN13: 3 | GO13: 3 | GP13: 3 | GQ13: 3 | GR13: 3 | GS13: 3 | GT13: 3 | GU13: 3 | GV13: 3 | GW13: 3 | GX13: 3 | GY13: 3 | GZ13: 3
A14: 2025/10/06 4:17:28 PM GMT+7 | B14: Saya bersedia menjadi responden dalam penelitian ini | C14: Pisri Andani | D14: Perempuan | E14: Dusun 1 Desa Lunas Jaya | F14: 085232616814 | G14: 21 | H14: Anak | I14: SMA/SMK | J14: Penduduk asli | K14: Staff Desa | L14: 500000 | M14: 100000 | N14: Ya | O14: 1 | P14: 10 | Q14: 180 | R14: Kontak kerabat;Hiburan;Mencari informasi;Membeli produk | S14: Ya | T14: 1 | U14: 10 | V14: 180 | W14: Kontak kerabat;Hiburan;Mencari informasi;Membeli produk | X14: Tidak | AC14: Tidak | AH14: Ya | AI14: 1 | AJ14: 2 | AK14: 120 | AL14: Lainnya | AM14: Ya | AN14: 1 | AO14: 30 | AP14: Hiburan | AQ14: Tidak | AU14: Ya | AV14: 1 | AW14: 30 | AX14: Hiburan;Mencari informasi | AY14: Ya | AZ14: 10 | BA14: 600 | BB14: Kontak kerabat;Hiburan;Mencari informasi | BC14: Ya | BD14: 5 | BE14: 300 | BF14: Hiburan;Mencari informasi;Membeli produk | BG14: Ya | BH14: 1 | BI14: 30 | BJ14: Hiburan | BK14: Tidak | BO14: Tidak | BS14: Tidak | BW14: Tidak | CA14: Tidak | CE14: 7 | CF14: 5 | CG14: Kemensos | CH14: 5 | CI14: 4 | CJ14: 6 | CK14: kemendikbud kemenag kemendes | CL14: 1 | CM14: 1 | CN14: 1 | CO14: tidak ada | CP14: 1 | CQ14: 1 | CR14: 1 | CS14: tidak ada | CT14: 4 | CU14: 4 | CV14: 4 | CW14: 4 | CX14: 4 | CY14: 4 | CZ14: 4 | DA14: 4 | DB14: 4 | DC14: 4 | DD14: 4 | DE14: 4 | DF14: 4 | DG14: 4 | DH14: 4 | DI14: 4 | DJ14: 4 | DK14: 4 | DL14: 4 | DM14: 4 | DN14: 4 | DO14: 4 | DP14: 4 | DQ14: 4 | DR14: 4 | DS14: 4 | DT14: 4 | DU14: 4 | DV14: 4 | DW14: 4 | DX14: 4 | DY14: tidak ada | DZ14: 4 | EA14: 4 | EB14: 4 | EC14: tidak ada | ED14: 4 | EE14: 4 | EF14: 4 | EG14: tidak ada | EH14: 4 | EI14: 4 | EJ14: 4 | EK14: tidak ada | EL14: 4 | EM14: 4 | EN14: 4 | EO14: 4 | EP14: 4 | EQ14: 4 | ER14: 4 | ES14: 4 | ET14: 4 | EU14: 4 | EV14: 4 | EW14: 4 | EX14: 4 | EY14: 4 | EZ14: 4 | FA14: 4 | FB14: 4 | FC14: 4 | FD14: 4 | FE14: 4 | FF14: 4 | FG14: 4 | FH14: 4 | FI14: 4 | FJ14: 4 | FK14: 3 | FL14: 3 | FM14: 3 | FN14: 3 | FO14: 3 | FP14: 3 | FQ14: 3 | FR14: 3 | FS14: 3 | FT14: 3 | FU14: 5 | FV14: 3 | FW14: 3 | FX14: 3 | FY14: 3 | FZ14: 3 | GA14: 3 | GB14: 3 | GC14: 3 | GD14: 3 | GE14: 3 | GF14: 3 | GG14: 3 | GH14: 3 | GI14: 3 | GJ14: 3 | GK14: 1 | GL14: 1 | GM14: 1 | GN14: 1 | GO14: 2 | GP14: 2 | GQ14: 2 | GR14: 2 | GS14: 3 | GT14: 3 | GU14: 2 | GV14: 1 | GW14: 2 | GX14: 6 | GY14: 1 | GZ14: 3
A15: 2025/10/06 5:37:13 PM GMT+7 | B15: Saya bersedia menjadi responden dalam penelitian ini | C15: Eris Julianti | D15: Perempuan | E15: Dusun ll Desa Lunas Jaya Kecamatan Tanah Abang kabupaten Penukal abab Lematang Ilir | F15: 082371773762 | G15: 26 | H15: Anak | I15: D4/S1 | J15: Penduduk asli | K15: Wirausaha | L15: 1000000 | M15: 150000 | N15: Ya | O15: 2 | P15: 20 | Q15: 10 menit | R15: Kontak kerabat;Mencari informasi;Membeli produk;Menjual produk;Lainnya | S15: Ya | T15: 2 | U15: 20 | V15: 10 menit | W15: Kontak kerabat;Mencari informasi;Membeli produk;Menjual produk;Lainnya | X15: Tidak | AC15: Tidak | AH15: Tidak | AM15: Ya | AN15: 2 | AO15: 2 menit | AP15: Kontak kerabat | AQ15: Tidak | AU15: Ya | AV15: 1 | AW15: 1 menit | AX15: Kontak kerabat | AY15: Ya | AZ15: 15 | BA15: 5 menit | BB15: Kontak kerabat;Menjual produk;Lainnya | BC15: Ya | BD15: 1 | BE15: 2 menit | BF15: Hiburan;Mencari informasi | BG15: Ya | BH15: 0 | BI15: 0 | BJ15: Mencari informasi | BK15: Tidak | BO15: Ya | BP15: 2 | BQ15: 10 menit | BR15: Membeli produk | BS15: Tidak | BW15: Tidak | CA15: Tidak | CE15: 2 | CF15: 2 | CG15: @paliterkini | CH15: 4 | CI15: 3 | CJ15: 3 | CK15: beranda/home | CL15: 4 | CM15: 3 | CN15: 1 | CO15: keluarga | CP15: 2 | CQ15: 2 | CR15: 2 | CS15: tidak ada | CT15: 2 | CU15: 2 | CV15: 2 | CW15: 2 | CX15: 2 | CY15: 2 | CZ15: 2 | DA15: 3 | DB15: 2 | DC15: 3 | DD15: 3 | DE15: 3 | DF15: 3 | DG15: 3 | DH15: 3 | DI15: 3 | DJ15: 3 | DK15: 3 | DL15: 3 | DM15: 3 | DN15: 3 | DO15: 3 | DP15: 3 | DQ15: 3 | DR15: 3 | DS15: 3 | DT15: 3 | DU15: 3 | DV15: 3 | DW15: 3 | DX15: 3 | DY15: tidak ada | DZ15: 3 | EA15: 3 | EB15: 3 | EC15: tidak ada | ED15: 3 | EE15: 3 | EF15: 3 | EG15: tidak ada | EH15: 3 | EI15: 3 | EJ15: 3 | EK15: tidak ada | EL15: 3 | EM15: 3 | EN15: 3 | EO15: 3 | EP15: 3 | EQ15: 3 | ER15: 3 | ES15: 3 | ET15: 3 | EU15: 3 | EV15: 3 | EW15: 3 | EX15: 3 | EY15: 3 | EZ15: 3 | FA15: 3 | FB15: 3 | FC15: 3 | FD15: 3 | FE15: 3 | FF15: 3 | FG15: 3 | FH15: 3 | FI15: 3 | FJ15: 3 | FK15: 3 | FL15: 3 | FM15: 3 | FN15: 3 | FO15: 3 | FP15: 3 | FQ15: 3 | FR15: 3 | FS15: 3 | FT15: 3 | FU15: 5 | FV15: 3 | FW15: 3 | FX15: 3 | FY15: 3 | FZ15: 3 | GA15: 3 | GB15: 3 | GC15: 3 | GD15: 3 | GE15: 3 | GF15: 3 | GG15: 3 | GH15: 3 | GI15: 3 | GJ15: 3 | GK15: 5 | GL15: 3 | GM15: 3 | GN15: 4 | GO15: 4 | GP15: 3 | GQ15: 3 | GR15: 3 | GS15: 3 | GT15: 3 | GU15: 3 | GV15: 3 | GW15: 3 | GX15: 3 | GY15: 3 | GZ15: 3
A16: 2025/10/06 5:47:44 PM GMT+7 | B16: Saya bersedia menjadi responden dalam penelitian ini | C16: Diah Suci Almuhyi | D16: Perempuan | E16: Dusun 2 desa lunas jaya kecamatan tanah abang kabupaten penukal abab Lematang ilir | F16: 082178029294 | G16: 26 | H16: Istri | I16: D4/S1 | J16: Pendatang | K16: Guru honorer | L16: 150000 | M16: 75000 | N16: Ya | O16: 1 | P16: 15 | Q16: 15 jam | R16: Kontak kerabat;Hiburan;Mencari informasi;Membeli produk;Lainnya | S16: Ya | T16: 1 | U16: 15 | V16: 15 | W16: Kontak kerabat;Hiburan;Mencari informasi;Membeli produk;Lainnya | X16: Tidak | AC16: Tidak | AH16: Tidak | AM16: Ya | AN16: 2 | AO16: 2 | AP16: Kontak kerabat;Hiburan;Mencari informasi | AQ16: Tidak | AU16: Ya | AV16: 1 | AW16: 1 | AX16: Hiburan;Mencari informasi | AY16: Ya | AZ16: 10 | BA16: 10 | BB16: Kontak kerabat;Mencari informasi | BC16: Ya | BD16: 5 | BE16: 4 | BF16: Hiburan;Mencari informasi;Membeli produk | BG16: Ya | BH16: 1 | BI16: 1 | BJ16: Mencari informasi | BK16: Tidak | BO16: Ya | BP16: 1 | BQ16: 1 | BR16: Membeli produk | BS16: Tidak | BW16: Tidak | CA16: Tidak | CE16: 1 | CF16: 3 | CG16: Saya lupa | CH16: 1 | CI16: 1 | CJ16: 1 | CK16: Saya melihat status di akun teman2 saya hanya untuk hiburan dan terkadang menjadi informasi | CL16: 1 | CM16: 3 | CN16: 2 | CO16: Grup sekolah yaitu dinama kan "Funtastic" | CP16: 6 | CQ16: 6 | CR16: 6 | CS16: YouTube latihan sscasn | CT16: 6 | CU16: 6 | CV16: 6 | CW16: 6 | CX16: 6 | CY16: 6 | CZ16: 6 | DA16: 6 | DB16: 6 | DC16: 6 | DD16: 6 | DE16: 6 | DF16: 6 | DG16: 6 | DH16: 6 | DI16: 6 | DJ16: 6 | DK16: 6 | DL16: 6 | DM16: 6 | DN16: 6 | DO16: 6 | DP16: 6 | DQ16: 6 | DR16: 6 | DS16: 6 | DT16: 6 | DU16: 6 | DV16: 6 | DW16: 6 | DX16: 6 | DY16: Akun resmi terkait | DZ16: 7 | EA16: 7 | EB16: 7 | EC16: Banyak sekali akun terkait namun saya ngecek di akun resmi | ED16: 6 | EE16: 7 | EF16: 7 | EG16: Funtastic | EH16: 7 | EI16: 7 | EJ16: 7 | EK16: Bkn | EL16: 7 | EM16: 7 | EN16: 7 | EO16: 7 | EP16: 7 | EQ16: 7 | ER16: 6 | ES16: 7 | ET16: 7 | EU16: 7 | EV16: 6 | EW16: 6 | EX16: 6 | EY16: 5 | EZ16: 6 | FA16: 6 | FB16: 6 | FC16: 6 | FD16: 6 | FE16: 6 | FF16: 6 | FG16: 6 | FH16: 6 | FI16: 6 | FJ16: 5 | FK16: 7 | FL16: 7 | FM16: 2 | FN16: 7 | FO16: 7 | FP16: 6 | FQ16: 6 | FR16: 6 | FS16: 6 | FT16: 6 | FU16: 2 | FV16: 2 | FW16: 2 | FX16: 7 | FY16: 7 | FZ16: 7 | GA16: 7 | GB16: 7 | GC16: 7 | GD16: 7 | GE16: 7 | GF16: 7 | GG16: 7 | GH16: 1 | GI16: 1 | GJ16: 7 | GK16: 7 | GL16: 7 | GM16: 7 | GN16: 7 | GO16: 7 | GP16: 7 | GQ16: 7 | GR16: 7 | GS16: 7 | GT16: 7 | GU16: 7 | GV16: 7 | GW16: 7 | GX16: 7 | GY16: 7 | GZ16: 7
A17: 2025/10/06 6:55:24 PM GMT+7 | B17: Saya bersedia menjadi responden dalam penelitian ini | C17: Duwi Arisa | D17: Perempuan | E17: Dusun 1 Lunas jaya | F17: 082364999692 | G17: 30 | H17: Istri | I17: SMP | J17: Penduduk asli | K17: Petani | L17: 3000000 | M17: 100000 | N17: Ya | O17: 1 | P17: 8 | Q17: 480 | R17: Kontak kerabat;Hiburan;Mencari informasi;Membeli produk;Lainnya | S17: Tidak | X17: Tidak | AC17: Tidak | AH17: Tidak | AM17: Ya | AN17: 10 | AO17: 600 | AP17: Kontak kerabat;Hiburan;Mencari informasi;Membeli produk;Lainnya | AQ17: Tidak | AU17: Tidak | AY17: Ya | AZ17: 12 | BA17: 30 | BB17: Kontak kerabat;Mencari informasi;Lainnya | BC17: Ya | BD17: 3 | BE17: 30 | BF17: Hiburan;Mencari informasi | BG17: Ya | BH17: 5 | BI17: 60 | BJ17: Hiburan;Mencari informasi;Lainnya | BK17: Tidak | BO17: Tidak | BS17: Tidak | BW17: Tidak | CA17: Tidak | CE17: 3 | CF17: 3 | CG17: YouTube, Facebook, WhatsApp. | CH17: 7 | CI17: 6 | CJ17: 6 | CK17: Facebook, WhatsApp | CL17: 6 | CM17: 7 | CN17: 7 | CO17: Semua grup yg ada . | CP17: 7 | CQ17: 6 | CR17: 6 | CS17: YouTube | CT17: 3 | CU17: 3 | CV17: 3 | CW17: 3 | CX17: 3 | CY17: 3 | CZ17: 3 | DA17: 6 | DB17: 6 | DC17: 6 | DD17: 6 | DE17: 6 | DF17: 6 | DG17: 6 | DH17: 7 | DI17: 6 | DJ17: 6 | DK17: 6 | DL17: 6 | DM17: 6 | DN17: 6 | DO17: 7 | DP17: 7 | DQ17: 7 | DR17: 7 | DS17: 7 | DT17: 7 | DU17: 7 | DV17: 3 | DW17: 3 | DX17: 3 | DY17: Website blog | DZ17: 6 | EA17: 6 | EB17: 6 | EC17: Facebook | ED17: 6 | EE17: 6 | EF17: 6 | EG17: Grup WhatsApp | EH17: 4 | EI17: 6 | EJ17: 6 | EK17: YouTube | EL17: 4 | EM17: 4 | EN17: 7 | EO17: 6 | EP17: 7 | EQ17: 5 | ER17: 5 | ES17: 5 | ET17: 6 | EU17: 7 | EV17: 7 | EW17: 5 | EX17: 4 | EY17: 3 | EZ17: 7 | FA17: 6 | FB17: 5 | FC17: 4 | FD17: 5 | FE17: 5 | FF17: 7 | FG17: 6 | FH17: 6 | FI17: 3 | FJ17: 3 | FK17: 2 | FL17: 3 | FM17: 3 | FN17: 3 | FO17: 3 | FP17: 3 | FQ17: 3 | FR17: 3 | FS17: 3 | FT17: 3 | FU17: 5 | FV17: 4 | FW17: 5 | FX17: 4 | FY17: 4 | FZ17: 5 | GA17: 4 | GB17: 4 | GC17: 4 | GD17: 4 | GE17: 4 | GF17: 4 | GG17: 4 | GH17: 4 | GI17: 4 | GJ17: 5 | GK17: 6 | GL17: 6 | GM17: 6 | GN17: 6 | GO17: 6 | GP17: 6 | GQ17: 6 | GR17: 6 | GS17: 6 | GT17: 6 | GU17: 6 | GV17: 6 | GW17: 5 | GX17: 5 | GY17: 6 | GZ17: 7
A18: 2025/10/06 7:26:49 PM GMT+7 | B18: Saya bersedia menjadi responden dalam penelitian ini | C18: Parhan Nadiansyah | D18: Laki-laki | E18: Lunas jaya dusun 3 | F18: 083852936578 | G18: 18 | H18: Anak | I18: SMA/SMK | J18: Penduduk asli | K18: Belum bekerja | L18: 0 | M18: 150 | N18: Ya | O18: 1 | P18: 2 | Q18: 60 | R18: Kontak kerabat;Hiburan;Mencari informasi;Membeli produk;Lainnya | S18: Ya | T18: 1 | U18: 2 | V18: 60 | W18: Kontak kerabat;Hiburan;Mencari informasi;Membeli produk;Lainnya | X18: Tidak | AC18: Tidak | AH18: Tidak | AM18: Tidak | AQ18: Tidak | AU18: Ya | AV18: 2 | AW18: 30 | AX18: Hiburan;Mencari informasi;Lainnya | AY18: Ya | AZ18: 2 | BA18: 30 | BB18: Kontak kerabat;Lainnya | BC18: Ya | BD18: 5 | BE18: 120 | BF18: Hiburan;Mencari informasi;Membeli produk;Lainnya | BG18: Ya | BH18: 1 | BI18: 10 | BJ18: Hiburan;Lainnya | BK18: Ya | BL18: 1 | BM18: 5 | BN18: Lainnya | BO18: Ya | BP18: 1 | BQ18: 5 | BR18: Membeli produk;Lainnya | BS18: Tidak | BW18: Tidak | CA18: Tidak | CE18: 6 | CF18: 5 | CG18: Chrome | CH18: 7 | CI18: 5 | CJ18: 5 | CK18: Tik tok | CL18: 1 | CM18: 1 | CN18: 1 | CO18: Tidak ada | CP18: 1 | CQ18: 1 | CR18: 1 | CS18: Tidak ada | CT18: 4 | CU18: 5 | CV18: 5 | CW18: 4 | CX18: 6 | CY18: 4 | CZ18: 7 | DA18: 6 | DB18: 4 | DC18: 6 | DD18: 4 | DE18: 6 | DF18: 6 | DG18: 7 | DH18: 7 | DI18: 5 | DJ18: 5 | DK18: 6 | DL18: 6 | DM18: 6 | DN18: 7 | DO18: 7 | DP18: 5 | DQ18: 5 | DR18: 5 | DS18: 6 | DT18: 5 | DU18: 7 | DV18: 6 | DW18: 5 | DX18: 5 | DY18: Chrome | DZ18: 7 | EA18: 5 | EB18: 6 | EC18: Tik tok | ED18: 4 | EE18: 4 | EF18: 5 | EG18: Berita Pali | EH18: 4 | EI18: 3 | EJ18: 5 | EK18: Tidak ada | EL18: 3 | EM18: 4 | EN18: 4 | EO18: 3 | EP18: 2 | EQ18: 1 | ER18: 2 | ES18: 2 | ET18: 3 | EU18: 3 | EV18: 3 | EW18: 3 | EX18: 1 | EY18: 1 | EZ18: 1 | FA18: 1 | FB18: 1 | FC18: 1 | FD18: 1 | FE18: 2 | FF18: 2 | FG18: 2 | FH18: 1 | FI18: 4 | FJ18: 4 | FK18: 4 | FL18: 4 | FM18: 4 | FN18: 3 | FO18: 4 | FP18: 5 | FQ18: 4 | FR18: 5 | FS18: 5 | FT18: 3 | FU18: 5 | FV18: 3 | FW18: 4 | FX18: 5 | FY18: 4 | FZ18: 4 | GA18: 5 | GB18: 3 | GC18: 3 | GD18: 5 | GE18: 3 | GF18: 5 | GG18: 2 | GH18: 3 | GI18: 5 | GJ18: 5 | GK18: 4 | GL18: 4 | GM18: 5 | GN18: 4 | GO18: 4 | GP18: 4 | GQ18: 4 | GR18: 5 | GS18: 5 | GT18: 4 | GU18: 5 | GV18: 4 | GW18: 5 | GX18: 5 | GY18: 4 | GZ18: 4
A19: 2025/10/06 7:33:28 PM GMT+7 | B19: Saya bersedia menjadi responden dalam penelitian ini | C19: Miftahul janna | D19: Perempuan | E19: Dusun 3 desa lunas jaya | F19: 082116869795 | G19: 26 | H19: Istri | I19: SMA/SMK | J19: Penduduk asli | K19: Ibu rumah tangga | L19: 1.500 | M19: 200 | N19: Ya | O19: 1 | P19: 2 | Q19: 6 jam | R19: Kontak kerabat;Hiburan;Mencari informasi | S19: Tidak | X19: Tidak | AC19: Tidak | AH19: Tidak | AM19: Ya | AN19: 2 | AO19: 3 jam | AP19: Kontak kerabat;Mencari informasi | AQ19: Tidak | AU19: Tidak | AY19: Ya | AZ19: 2 | BA19: 4 jam | BB19: Kontak kerabat | BC19: Tidak | BG19: Ya | BH19: 1 | BI19: 20 | BJ19: Hiburan | BK19: Tidak | BO19: Tidak | BS19: Tidak | BW19: Tidak | CA19: Tidak | CE19: 1 | CF19: 1 | CG19: Facebook | CH19: 7 | CI19: 7 | CJ19: 7 | CK19: Facebook | CL19: 7 | CM19: 7 | CN19: 3 | CO19: Grup keluarga | CP19: 7 | CQ19: 7 | CR19: 7 | CS19: Youtube | CT19: 7 | CU19: 7 | CV19: 3 | CW19: 3 | CX19: 3 | CY19: 3 | CZ19: 3 | DA19: 7 | DB19: 7 | DC19: 7 | DD19: 7 | DE19: 7 | DF19: 7 | DG19: 7 | DH19: 7 | DI19: 7 | DJ19: 7 | DK19: 7 | DL19: 7 | DM19: 7 | DN19: 7 | DO19: 7 | DP19: 7 | DQ19: 7 | DR19: 7 | DS19: 7 | DT19: 7 | DU19: 7 | DV19: 3 | DW19: 3 | DX19: 3 | DY19: Tidak ada | DZ19: 7 | EA19: 7 | EB19: 7 | EC19: Facebook | ED19: 3 | EE19: 3 | EF19: 7 | EG19: Grup pkk | EH19: 3 | EI19: 3 | EJ19: 3 | EK19: Youtube | EL19: 3 | EM19: 3 | EN19: 3 | EO19: 3 | EP19: 3 | EQ19: 3 | ER19: 3 | ES19: 3 | ET19: 3 | EU19: 7 | EV19: 7 | EW19: 3 | EX19: 3 | EY19: 3 | EZ19: 3 | FA19: 3 | FB19: 3 | FC19: 3 | FD19: 3 | FE19: 3 | FF19: 3 | FG19: 7 | FH19: 3 | FI19: 3 | FJ19: 7 | FK19: 3 | FL19: 3 | FM19: 3 | FN19: 3 | FO19: 3 | FP19: 3 | FQ19: 3 | FR19: 3 | FS19: 3 | FT19: 3 | FU19: 5 | FV19: 3 | FW19: 3 | FX19: 3 | FY19: 3 | FZ19: 3 | GA19: 3 | GB19: 3 | GC19: 3 | GD19: 3 | GE19: 3 | GF19: 3 | GG19: 3 | GH19: 3 | GI19: 3 | GJ19: 3 | GK19: 7 | GL19: 7 | GM19: 7 | GN19: 7 | GO19: 3 | GP19: 3 | GQ19: 3 | GR19: 3 | GS19: 3 | GT19: 3 | GU19: 3 | GV19: 3 | GW19: 3 | GX19: 7 | GY19: 1 | GZ19: 3
A20: 2025/10/06 8:12:43 PM GMT+7 | B20: Saya bersedia menjadi responden dalam penelitian ini | C20: Riski Ariska | D20: Perempuan | E20: Dusun 3 desa lunas jaya | F20: 082178696023 | G20: 28 | H20: Istri | I20: SMP | J20: Pendatang | K20: Petani | L20: 1600.000 | M20: 100.000 | N20: Ya | O20: 1 | P20: 10 | Q20: 30 | R20: Kontak kerabat;Hiburan;Mencari informasi;Membeli produk | S20: Tidak | X20: Tidak | AC20: Tidak | AH20: Tidak | AM20: Ya | AN20: 6 | AO20: 20 menit | AP20: Kontak kerabat;Hiburan;Mencari informasi;Membeli produk | AQ20: Tidak | AU20: Tidak | AY20: Ya | AZ20: 10 | BA20: 5 menit | BB20: Kontak kerabat;Hiburan;Mencari informasi | BC20: Ya | BD20: 10 | BE20: 20 | BF20: Kontak kerabat;Hiburan;Mencari informasi;Membeli produk | BG20: Tidak | BK20: Tidak | BO20: Ya | BP20: 1 | BQ20: 20 menit | BR20: Mencari informasi;Membeli produk | BS20: Tidak | BW20: Tidak | CA20: Tidak | CE20: 4 | CF20: 7 | CG20: Tik tok, facebook | CH20: 7 | CI20: 7 | CJ20: 7 | CK20: Facebook dan tiktok | CL20: 7 | CM20: 7 | CN20: 7 | CO20: Grup messenger | CP20: 1 | CQ20: 1 | CR20: 1 | CS20: Tidak ada | CT20: 4 | CU20: 7 | CV20: 7 | CW20: 4 | CX20: 4 | CY20: 3 | CZ20: 7 | DA20: 7 | DB20: 7 | DC20: 7 | DD20: 1 | DE20: 7 | DF20: 7 | DG20: 7 | DH20: 7 | DI20: 7 | DJ20: 7 | DK20: 1 | DL20: 7 | DM20: 7 | DN20: 7 | DO20: 1 | DP20: 1 | DQ20: 1 | DR20: 1 | DS20: 1 | DT20: 1 | DU20: 1 | DV20: 7 | DW20: 7 | DX20: 7 | DY20: Tik tok dan WhatsApp | DZ20: 7 | EA20: 7 | EB20: 7 | EC20: Tiktok dan WhatsApp | ED20: 7 | EE20: 7 | EF20: 7 | EG20: Tiktok dan messenger | EH20: 1 | EI20: 1 | EJ20: 4 | EK20: YouTube resep masakan | EL20: 1 | EM20: 4 | EN20: 1 | EO20: 1 | EP20: 6 | EQ20: 7 | ER20: 7 | ES20: 7 | ET20: 1 | EU20: 1 | EV20: 7 | EW20: 7 | EX20: 1 | EY20: 1 | EZ20: 1 | FA20: 1 | FB20: 1 | FC20: 1 | FD20: 1 | FE20: 1 | FF20: 1 | FG20: 1 | FH20: 1 | FI20: 7 | FJ20: 7 | FK20: 7 | FL20: 7 | FM20: 1 | FN20: 7 | FO20: 7 | FP20: 7 | FQ20: 7 | FR20: 7 | FS20: 7 | FT20: 1 | FU20: 7 | FV20: 1 | FW20: 1 | FX20: 7 | FY20: 1 | FZ20: 7 | GA20: 1 | GB20: 7 | GC20: 1 | GD20: 7 | GE20: 1 | GF20: 7 | GG20: 1 | GH20: 1 | GI20: 1 | GJ20: 7 | GK20: 7 | GL20: 7 | GM20: 7 | GN20: 7 | GO20: 7 | GP20: 7 | GQ20: 1 | GR20: 7 | GS20: 7 | GT20: 7 | GU20: 7 | GV20: 7 | GW20: 7 | GX20: 1 | GY20: 7 | GZ20: 7
